Workbook

Sheet COS coding
G1: id | H1: contributors | I1: date_entered | J1: date_updated | K1: notes_coder | L1: notes_validation | M1: ref_original | N1: doi_original | O1: study_original | R1: ref_replication | S1: doi_replication | T1: osf_link | U1: study_replication | Y1: exclusion | Z1: discipline | AA1: effect | AB1: tags | AC1: description | AD1: claim_text_orig | AE1: claim_text_orig_page | AF1: n_original | AG1: es_orig_value | AH1: es_orig_estype | AJ1: pval_value_o | AK1: pval_type_o | AL1: pval_tails_o | AO1: n_replication | AP1: es_rep_value | AQ1: es_rep_estype | AS1: pval_value_r | AT1: pval_type_r | AU1: pval_tails_r
A2: rowid | B2: status | C2: approach | D2: coder_1 | E2: coder_2 | F2: entry | G2: id | H2: contributors | I2: date_entered | J2: date_updated | K2: notes_coder | L2: notes_validation | M2: ref_o | N2: doi_o | O2: study_o | P2: file_o | Q2: link_o | R2: ref_r | S2: doi_r | T2: url_r | U2: study_r | V2: file_r | W2: label_r | X2: link_r | Y2: exclusion | Z2: discipline | AA2: effect | AB2: tags | AC2: description | AD2: claim_text_o | AE2: claim_page_o | AF2: n_o | AG2: es_value_o | AH2: es_type_o | AI2: es_repr_o | AJ2: pval_value_o | AK2: pval_type_o | AL2: pval_tails_o | AM2: nested_o | AN2: prereg_o | AO2: n_r | AP2: es_value_r | AQ2: es_type_r | AR2: es_repr_r | AS2: pval_value_r | AT2: pval_type_r | AU2: pval_tails_r | AV2: nested_r | AW2: prereg_r | AX2: closeness_r | AY2: outcome | AZ2: outcome_quote | BA2: out_quote_source | BB2: fred_id | BC2: feedback_for_coder | BD2: validator
A3: ENSURE THIS STAYS UNCHANGED AND ALIGNED! | B3: - assigned: the entry has been assigned to a coder - help needed: there is an unresolved conflict - validated - chosen: the entry has been validated and marked as the one to remain in the final dataset - validated - discarded: the entry has been used for validation and is now inferior or redundant to the chosen entry for the same finding - validated - FReD but not COS: applies to replication studies that do not contain statistical test (e.g., replications in the qualitative humanities) | F3: for data matching. DO NOT EDIT - keep blank for new rows | G3: Sample id. DO NOT CHANGE. If you add samples, copy and add _b, _c etc | H3: *Add* your name when you edit the row | I3: (dd/mm/yyyy) | J3: (dd/mm/yyyy) | K3: general data entry notes, e.g., re access issues or study selection | L3: only used by core team | M3: Copy APA style from Google Scholar (or similar), without DOI | N3: without URL prefix, so starting with 10.xx | O3: Number of study in paper, e.g., 1 or 2A | P3: file-name for O PDF - only edit if DOI is missing | R3: Copy APA style from Google Scholar (or similar), without DOI | S3: without URL prefix, so starting with 10.xx | T3: Link to R results - only when DOI missing or for aggregate report | U3: Number of study in paper, e.g., 1 or 2A | V3: file-name for R PDF - only edit if DOI is missing | W3: How does R identify as replication in title or abstract? Usually "replication" but report different wording if used | Y3: Reason for study exclusion (usually only if R is not a replication) | Z3: Which broad field does the finding come from - e.g., Social Psychology or Labor Economics | AA3: x | AB3: tags to increase findability - e.g. keywords from abstract | AC3: Description of the effect under investigation (e.g., x is associated with y, x leads to y), possibly a part of the original publication's title (abstract claim) | AD3: The authors’ key statistical result and its interpretation | AE3: Page number(s) for claim_text_o | AF3: O's sample size [used for the critical test, i.e., after exclusion criteria have been applied], must contain only one value and must not contain text | AG3: original effect size value, must contain only one value and must not contain text | AH3: original effect size type (e.g., d, r, r², etasq) | AI3: Reproducible origin/calculation method for es_value_o ("p. xx" when reported, link when available online - e.g., OSF, otherwise calculation process) | AJ3: The reported p-value associated with the original finding, must contain only one value and must not contain text | AK3: How is p-val reported? "=" (e) / "<" (l) / ">" (g) or combined (le, ge)? for example "p <= .05" should be coded as "le" | AL3: How many tails associated with the p-value, taking on values of one, two, or unknown one: 1 two: 2 unknown / not specified: NA missing: not coded | AM3: Is pval based on a test that accounts for dependence between observations (e.g., multilevel, repeated measures) | AN3: Link to preregistration of O (only search for "regist") | AO3: R's sample size [used for the critical test, i.e., after exclusion criteria have been applied], must contain only one value and must not contain text | AP3: replication effect size value, must contain only one value and must not contain text | AQ3: replication effect size type | AR3: Reproducible origin/calculation method for es_value_r ("p. xx" when reported, otherwise calculation process) | AS3: The reported p-value associated with the replication finding, must contain only one value and must not contain text | AT3: How is p-val reported? "=" (e) / "<" (l) / ">" (g) or combined (le, ge)? for example "p <= .05" should be coded as "le" | AU3: How many tails associated with the p-value, taking on values of one, two, or unknown one: 1 two: 2 unknown: NA missing: not coded | AV3: Is pval based on a test that accounts for dependence between observations (e.g., multilevel, repeated measures) | AW3: Link to preregistration of R (only search for "regist") | AX3: NA: unknown 1: internal: all central features are highly similar AND conducted by at least one of the original researchers 2: close/direct: central features are highly similar AND none of the original authors is involved 3: conceptual/constructive/extension: central features are different, theoretically relevant aspects are the same; authorship overlap is irrelevant | AY3: One of successful failed mixed uninformative statistically successful but flawed | AZ3: outcome statement by replication authors | BA3: source of the quote | BD3: name of the person who validated the entry
A4: 4 | B4: validated - discarded | C4: double | F4: 2zgf9_1 | G4: 2zgf9 | H4: Kateri McRae, Daniel Lumian, Mallory C. Kidwell, Johanna Cohoon, Lilian Hummer | I4: 1.1.2023 | J4: 45641 | K4: coding tasks 2zgf9_1, bth36_1, and 7vgkq_1 are similar; the partial-eta squared reported in the replication paper of 0.226 is different from the value in OSF registries of 0.313, hence requires validation; Psychological science has not been listed as one of the disciplines, hence categorizing them as political science | M4: Cunningham, W. A., Van Bavel, J. J., & Johnsen, I. R. (2008). Affective flexibility: evaluative processing goals shape amygdala activity. Psychological Science, 19(2), 152-160. | N4: 10.1111/j.1467-9280.2008.02061.x | O4: 1 | P4: 10.1111--j.1467-9280.2008.02061.x.pdf | Q4: {=if(iserror(MATCH(V4, 'File Links'!C:C, 0)), "N/A", HYPERLINK(INDEX('File Links'!B:B, MATCH(P4, 'File Links'!C:C, 0))))} -> https://drive.google.com/file/d/1HsW-lUSPFaIpISHQ1bNk6CKMtH3z9rau/view?usp=drivesdk | R4: McRae, K., & Lumian, D. S. (2023, September 28). Replication of WA Cunningham, JJ Van Bavel, IR Johnsen (2008, PS 19 (2)). https://doi.org/10.17605/OSF.IO/2ZGF9 | S4: 10.17605/OSF.IO/2ZGF9 | U4: 1 | V4: 10.17605--osf.io--2zgf9.pdf | W4: replication attempt | X4: {=if(iserror(MATCH(V4, 'File Links'!C:C, 0)), "N/A", HYPERLINK(INDEX('File Links'!B:B, MATCH(V4, 'File Links'!C:C, 0))))} -> https://drive.google.com/file/d/15dLELTosbF1NWFYI0UOSPLIC70dnGG5S/view?usp=drivesdk | Z4: Political Science | AB4: affective flexibility, amygdala, valence, stimulus | AC4: interaction between scanning condition (positive or negative) and stimulus valence | AD4: "results were consistent with the idea of affective flexibility. There was a significant interaction between scanning condition (positive or negative) and stimulus valence (postscan ratings of positivity or negativity), F(1, 11) = 9.67, p < .01, prep = .95" | AE4: p. 7 | AF4: 12 | AG4: F(1, 11) = 9.67 | AH4: test statistic | AI4: p. 7 | AJ4: 0.01 | AK4: l (<) | AL4: 2 (two) | AM4: no | AN4: NA | AO4: 39 | AP4: 0.226 | AQ4: etasq | AR4: p. 6 | AS4: 0.02 | AT4: l (<) | AU4: 2 (two) | AV4: yes | AW4: https://doi.org/10.17605/OSF.IO/2ZGF9 | AX4: 2 - close | AY4: =IFERROR(__xludf.DUMMYFUNCTION("vlookup(BB4,importrange(""https://docs.google.com/spreadsheets/d/1d2vevQ_7D_v35q4wCQ4RpQ_IPoTwEMB9Yp6ymwlPqew/edit?gid=984458430#gid=984458430"", ""'replication success'!A:K""), 11, FAlSE)"),"#N/A") -> #N/A | AZ4: =IFERROR(__xludf.DUMMYFUNCTION("vlookup(BB4,importrange(""https://docs.google.com/spreadsheets/d/1d2vevQ_7D_v35q4wCQ4RpQ_IPoTwEMB9Yp6ymwlPqew/edit?gid=984458430#gid=984458430"", ""'replication success'!A:M""), 12, FAlSE)"),"#N/A") -> #N/A | BA4: =IFERROR(__xludf.DUMMYFUNCTION("vlookup(BB4,importrange(""https://docs.google.com/spreadsheets/d/1d2vevQ_7D_v35q4wCQ4RpQ_IPoTwEMB9Yp6ymwlPqew/edit?gid=984458430#gid=984458430"", ""'replication success'!A:M""), 13, FAlSE)"),"#N/A") -> #N/A | BB4: =IFERROR(__xludf.DUMMYFUNCTION("REGEXREPLACE(G4, ""_[a-z]{1,2}$"", """")"),"2zgf9") -> 2zgf9 | BD4: LR
A5: 5 | B5: validated - discarded | C5: double | D5: Maureen | F5: 2zgf9_1 | G5: 2zgf9 | H5: Kateri McRae, Daniel Lumian, Mallory C. Kidwell, Johanna Cohoon, Lilian Hummer, Jyoti Bhogal | I5: 45108 | J5: 45644 | M5: Cunningham, W. A., Van Bavel, J. J., & Johnsen, I. R. (2008). Affective flexibility: evaluative processing goals shape amygdala activity. Psychological Science, 19(2), 152-160. | N5: 10.1111/j.1467-9280.2008.02061.x | O5: 1 | P5: 10.1111--j.1467-9280.2008.02061.x.pdf | Q5: {=if(iserror(MATCH(V5, 'File Links'!C:C, 0)), "N/A", HYPERLINK(INDEX('File Links'!B:B, MATCH(P5, 'File Links'!C:C, 0))))} -> https://drive.google.com/file/d/1HsW-lUSPFaIpISHQ1bNk6CKMtH3z9rau/view?usp=drivesdk | R5: McRae, K., & Lumian, D. S. (2023, September 28). Replication of WA Cunningham, JJ Van Bavel, IR Johnsen (2008, PS 19 (2)). https://doi.org/10.17605/OSF.IO/2ZGF9 | S5: 10.17605/OSF.IO/2ZGF9 | V5: 10.17605--osf.io--2zgf9.pdf | X5: {=if(iserror(MATCH(V5, 'File Links'!C:C, 0)), "N/A", HYPERLINK(INDEX('File Links'!B:B, MATCH(V5, 'File Links'!C:C, 0))))} -> https://drive.google.com/file/d/15dLELTosbF1NWFYI0UOSPLIC70dnGG5S/view?usp=drivesdk | Y5: no replication report available but only a post completion registration | Z5: Cognitive Psychology | AB5: affective flexibility, amygdala, positive names, negative names | AF5: 12 | AN5: NA | AP5: 0.313 | AS5: unavailable | AX5: 3 - conceptual | AY5: =IFERROR(__xludf.DUMMYFUNCTION("vlookup(BB5,importrange(""https://docs.google.com/spreadsheets/d/1d2vevQ_7D_v35q4wCQ4RpQ_IPoTwEMB9Yp6ymwlPqew/edit?gid=984458430#gid=984458430"", ""'replication success'!A:K""), 11, FAlSE)"),"#N/A") -> #N/A | AZ5: =IFERROR(__xludf.DUMMYFUNCTION("vlookup(BB5,importrange(""https://docs.google.com/spreadsheets/d/1d2vevQ_7D_v35q4wCQ4RpQ_IPoTwEMB9Yp6ymwlPqew/edit?gid=984458430#gid=984458430"", ""'replication success'!A:M""), 12, FAlSE)"),"#N/A") -> #N/A | BA5: =IFERROR(__xludf.DUMMYFUNCTION("vlookup(BB5,importrange(""https://docs.google.com/spreadsheets/d/1d2vevQ_7D_v35q4wCQ4RpQ_IPoTwEMB9Yp6ymwlPqew/edit?gid=984458430#gid=984458430"", ""'replication success'!A:M""), 13, FAlSE)"),"#N/A") -> #N/A | BB5: =IFERROR(__xludf.DUMMYFUNCTION("REGEXREPLACE(G5, ""_[a-z]{1,2}$"", """")"),"2zgf9") -> 2zgf9 | BD5: LR
A6: 6 | B6: validated - chosen | C6: double | D6: Nikita | F6: 39xuw_1 | G6: 39xuw | H6: Nikita | I6: 45638 | J6: 45680 | K6: 1. Values for the REPLICATION statistical inferences were taken from Files uploaded to OSF by a link: https://osf.io/39xuw/files/osfstorage. I merged them in the corresponding PDF | L6: corrected N from 150 to 137 | M6: Schaffer, J., & Knobe, J. (2012). Contrastive knowledge surveyed. Noûs, 46(4), 675-708. | N6: 10.1111/j.1468-0068.2010.00795.x | O6: 1 | P6: 10.1111--j.1468-0068.2010.00795.x.pdf | Q6: {=if(iserror(MATCH(V6, 'File Links'!C:C, 0)), "N/A", HYPERLINK(INDEX('File Links'!B:B, MATCH(P6, 'File Links'!C:C, 0))))} -> https://drive.google.com/file/d/1O4mjB0-ZSujMTJYtaAoIsXTPuhxgEF-0/view?usp=drivesdk | R6: Wilkenfeld, D. A., & Hernández-Conde, J. V. (2017, September 12). Schaffer and Knobe Replication. https://doi.org/10.17605/OSF.IO/39XUW | S6: osf.io/wru8c | U6: 1 | V6: osf.io--wru8c.pdf | W6: Replication | X6: {=if(iserror(MATCH(V6, 'File Links'!C:C, 0)), "N/A", HYPERLINK(INDEX('File Links'!B:B, MATCH(V6, 'File Links'!C:C, 0))))} -> https://drive.google.com/file/d/1Oux4UBwSd26986fxRHjyI5XNtU-07DOs/view?usp=drivesdk | Z6: Experimental Philosophy | AA6: Contrast sensitivity of knowledge ascription (contrastivism) | AB6: Contrastivism, knowledge, knowledge ascription, "rather than" clause, contrast, context | AC6: The two conditions of the experiment involve ascribing knowledge of the very same proposition ("rather than" clause) and they differ only in that they pick out two different contrasts to that proposition: subject or object. | AD6: "Participants in the thief contrast condition tended to agree with the knowledge ascription they received (mean rating: 4.6), while participants in the jewel contrast condition tended to disagree with the knowledge ascription they received (mean rating: 3.1)." | AE6: 16 | AF6: 100 | AG6: t(98) = 3.4 | AH6: test statistic | AI6: p.31 | AJ6: 0.001 | AK6: e (=) | AL6: 2 (two) | AM6: no | AN6: NA | AO6: 137 | AP6: 0.584 | AQ6: d | AR6: p.2 of https://osf.io/k2cna | AS6: 0.001 | AT6: l (<) | AU6: 2 (two) | AV6: no | AW6: https://osf.io/39xuw | AX6: 2 - close | AY6: =IFERROR(__xludf.DUMMYFUNCTION("vlookup(BB6,importrange(""https://docs.google.com/spreadsheets/d/1d2vevQ_7D_v35q4wCQ4RpQ_IPoTwEMB9Yp6ymwlPqew/edit?gid=984458430#gid=984458430"", ""'replication success'!A:K""), 11, FAlSE)"),"successful") -> successful | AZ6: =IFERROR(__xludf.DUMMYFUNCTION("vlookup(BB6,importrange(""https://docs.google.com/spreadsheets/d/1d2vevQ_7D_v35q4wCQ4RpQ_IPoTwEMB9Yp6ymwlPqew/edit?gid=984458430#gid=984458430"", ""'replication success'!A:M""), 12, FAlSE)"),"Success assessment:(Did you succeed in replicating the original result? If applicable, does the original teamagree with you?)Yes on both counts.") -> Success assessment:(Did you succeed in replicating the original result? If applicable, does the original teamagree with you?)Yes on both counts. | BA6: =IFERROR(__xludf.DUMMYFUNCTION("vlookup(BB6,importrange(""https://docs.google.com/spreadsheets/d/1d2vevQ_7D_v35q4wCQ4RpQ_IPoTwEMB9Yp6ymwlPqew/edit?gid=984458430#gid=984458430"", ""'replication success'!A:M""), 13, FAlSE)"),"pg.3 in https://osf.io/k2cna") -> pg.3 in https://osf.io/k2cna | BB6: =IFERROR(__xludf.DUMMYFUNCTION("REGEXREPLACE(G6, ""_[a-z]{1,2}$"", """")"),"39xuw") -> 39xuw | BD6: LR
A7: 7 | B7: validated - discarded | C7: double | D7: Husnain | F7: 39xuw_1 | G7: 39xuw | H7: Husnain | I7: 45641 | J7: 45680 | K7: 1. The tags are not given explicitly so I have inferred from the introduction of orignal paper. 2. The effect size is not reprted in the orignal study while replication has reported it's own and the effect size of replication study the infered effect size is cohen's d 0.687. 3. The replication paper has reported cohen's d for the replicated study without the p value, however, it presented p valur for test stastic without the value of t. | M7: Schaffer, J., & Knobe, J. (2012). Contrastive knowledge surveyed. Noûs, 46(4), 675-708. | N7: 10.1111/j.1468-0068.2010.00795.x | P7: 10.1111--j.1468-0068.2010.00795.x.pdf | Q7: {=if(iserror(MATCH(V7, 'File Links'!C:C, 0)), "N/A", HYPERLINK(INDEX('File Links'!B:B, MATCH(P7, 'File Links'!C:C, 0))))} -> https://drive.google.com/file/d/1O4mjB0-ZSujMTJYtaAoIsXTPuhxgEF-0/view?usp=drivesdk | R7: Wilkenfeld, D. A., & Hernández-Conde, J. V. (2017, September 12). Schaffer and Knobe Replication. https://doi.org/10.17605/OSF.IO/39XUW | S7: osf.io/wru8c | V7: osf.io--wru8c.pdf | W7: Replication | X7: {=if(iserror(MATCH(V7, 'File Links'!C:C, 0)), "N/A", HYPERLINK(INDEX('File Links'!B:B, MATCH(V7, 'File Links'!C:C, 0))))} -> https://drive.google.com/file/d/1Oux4UBwSd26986fxRHjyI5XNtU-07DOs/view?usp=drivesdk | Z7: Experimental Philosophy | AA7: contrastive knowledge | AB7: contrastive model, invariantist models, contextualist models, knowlege acriptions, conversational context | AC7: Thief contrast codition tend to agree more compared to jewel contrast condition with knowledge ascription | AD7: "N = 100 people spending time in the Canberra Centre Mall in Canberra, Australia, t (98) = 3.4, p = .001." | AE7: p. 16 | AF7: 100 | AG7: 3.4 | AH7: test statistic | AI7: p. 16, 31 | AJ7: 0.001 | AK7: e (=) | AL7: NA (not reported) | AM7: no | AN7: NA | AO7: 137 | AP7: 0.584 | AQ7: d | AR7: p. 1,2 | AW7: https://osf.io/39xuw | AX7: 2 - close | AY7: =IFERROR(__xludf.DUMMYFUNCTION("vlookup(BB7,importrange(""https://docs.google.com/spreadsheets/d/1d2vevQ_7D_v35q4wCQ4RpQ_IPoTwEMB9Yp6ymwlPqew/edit?gid=984458430#gid=984458430"", ""'replication success'!A:K""), 11, FAlSE)"),"successful") -> successful | AZ7: =IFERROR(__xludf.DUMMYFUNCTION("vlookup(BB7,importrange(""https://docs.google.com/spreadsheets/d/1d2vevQ_7D_v35q4wCQ4RpQ_IPoTwEMB9Yp6ymwlPqew/edit?gid=984458430#gid=984458430"", ""'replication success'!A:M""), 12, FAlSE)"),"Success assessment:(Did you succeed in replicating the original result? If applicable, does the original teamagree with you?)Yes on both counts.") -> Success assessment:(Did you succeed in replicating the original result? If applicable, does the original teamagree with you?)Yes on both counts. | BA7: =IFERROR(__xludf.DUMMYFUNCTION("vlookup(BB7,importrange(""https://docs.google.com/spreadsheets/d/1d2vevQ_7D_v35q4wCQ4RpQ_IPoTwEMB9Yp6ymwlPqew/edit?gid=984458430#gid=984458430"", ""'replication success'!A:M""), 13, FAlSE)"),"pg.3 in https://osf.io/k2cna") -> pg.3 in https://osf.io/k2cna | BB7: =IFERROR(__xludf.DUMMYFUNCTION("REGEXREPLACE(G7, ""_[a-z]{1,2}$"", """")"),"39xuw") -> 39xuw | BD7: LR
A8: 8 | B8: validated - discarded | C8: double | D8: Maureen | F8: 7vgkq_1 | G8: 7vgkq | H8: Kateri McRae, Mallory C. Kidwell, Johanna Cohoon, Daniel Lumian, Lilian Hummer, TESS-Experiments | I8: 1.1.2023 | J8: 45641 | K8: coding tasks 2zgf9_1, bth36_1, and 7vgkq_1 are similar; the partial-eta squared reported in the replication paper of 0.226 is different from the value in OSF registries of 0.313, hence requires validation; Psychological science has not been listed as one of the disciplines, hence categorizing them as political science | M8: Cunningham, W. A., Van Bavel, J. J., & Johnsen, I. R. (2008). Affective flexibility: evaluative processing goals shape amygdala activity. Psychological Science, 19(2), 152-160. | N8: 10.1111/j.1467-9280.2008.02061.x | O8: 1 | P8: 10.1111--j.1467-9280.2008.02061.x.pdf | Q8: {=if(iserror(MATCH(V8, 'File Links'!C:C, 0)), "N/A", HYPERLINK(INDEX('File Links'!B:B, MATCH(P8, 'File Links'!C:C, 0))))} -> https://drive.google.com/file/d/1HsW-lUSPFaIpISHQ1bNk6CKMtH3z9rau/view?usp=drivesdk | R8: McRae, K., Lumian, D. S., & T. (2023, September 28). Materials. https://doi.org/10.17605/OSF.IO/7VGKQ | S8: osf.io/x4v53 | V8: =hyperlink(vlookup(lower(S8),'File Links'!E:F, 2, FALSE), SUBSTITUTE(lower(S8), "/", "--") & ".pdf") -> osf.io--x4v53.pdf | W8: replication attempt | X8: {=if(iserror(MATCH(V8, 'File Links'!C:C, 0)), "N/A", HYPERLINK(INDEX('File Links'!B:B, MATCH(V8, 'File Links'!C:C, 0))))} -> https://drive.google.com/file/d/101OwdNXwjKk-CSJMDDNBxSMU_jnE0JGh/view?usp=drivesdk | Z8: Political Science | AB8: affective flexibility, amygdala, valence, stimulus | AE8: p. 7 | AF8: 12 | AG8: 9.67 | AH8: test statistic | AI8: p. 7 | AJ8: 0.01 | AK8: l (<) | AL8: 2 (two) | AM8: no | AN8: NA | AO8: 39 | AP8: 0.226 | AQ8: etasq | AR8: p. 6 | AS8: 0.02 | AT8: l (<) | AU8: 2 (two) | AV8: yes | AW8: https://doi.org/10.17605/OSF.IO/7VGKQ | AX8: 2 - close | AY8: =IFERROR(__xludf.DUMMYFUNCTION("vlookup(BB8,importrange(""https://docs.google.com/spreadsheets/d/1d2vevQ_7D_v35q4wCQ4RpQ_IPoTwEMB9Yp6ymwlPqew/edit?gid=984458430#gid=984458430"", ""'replication success'!A:K""), 11, FAlSE)"),"#N/A") -> #N/A | AZ8: =IFERROR(__xludf.DUMMYFUNCTION("vlookup(BB8,importrange(""https://docs.google.com/spreadsheets/d/1d2vevQ_7D_v35q4wCQ4RpQ_IPoTwEMB9Yp6ymwlPqew/edit?gid=984458430#gid=984458430"", ""'replication success'!A:M""), 12, FAlSE)"),"#N/A") -> #N/A | BA8: =IFERROR(__xludf.DUMMYFUNCTION("vlookup(BB8,importrange(""https://docs.google.com/spreadsheets/d/1d2vevQ_7D_v35q4wCQ4RpQ_IPoTwEMB9Yp6ymwlPqew/edit?gid=984458430#gid=984458430"", ""'replication success'!A:M""), 13, FAlSE)"),"#N/A") -> #N/A | BB8: =IFERROR(__xludf.DUMMYFUNCTION("REGEXREPLACE(G8, ""_[a-z]{1,2}$"", """")"),"7vgkq") -> 7vgkq | BD8: LR
A9: 9 | B9: validated - discarded | C9: double | D9: Jyoti | F9: 7vgkq_1 | G9: 7vgkq | H9: Kateri McRae, Mallory C. Kidwell, Johanna Cohoon, Daniel Lumian, Lilian Hummer, TESS-Experiments, Jyoti Bhogal | I9: 45170 | J9: 45644 | M9: Cunningham, W. A., Van Bavel, J. J., & Johnsen, I. R. (2008). Affective flexibility: evaluative processing goals shape amygdala activity. Psychological Science, 19(2), 152-160. | N9: 10.1111/j.1467-9280.2008.02061.x | O9: 1 | P9: 10.1111--j.1467-9280.2008.02061.x.pdf | Q9: NA | R9: McRae, K., Lumian, D. S., & T. (2023, September 28). Materials. https://doi.org/10.17605/OSF.IO/7VGKQ | S9: 10.17605/OSF.IO/7VGKQ | V9: 10.17605--osf.io--7vgkq.pdf | X9: {=if(iserror(MATCH(V9, 'File Links'!C:C, 0)), "N/A", HYPERLINK(INDEX('File Links'!B:B, MATCH(V9, 'File Links'!C:C, 0))))} -> N/A | Y9: no replication report available but only a post completion registration | Z9: Cognitive Psychology | AB9: affective flexibility, amygdala, positive names, negative names | AN9: NA | AP9: 0.313 | AS9: unavailable | AY9: =IFERROR(__xludf.DUMMYFUNCTION("vlookup(BB9,importrange(""https://docs.google.com/spreadsheets/d/1d2vevQ_7D_v35q4wCQ4RpQ_IPoTwEMB9Yp6ymwlPqew/edit?gid=984458430#gid=984458430"", ""'replication success'!A:K""), 11, FAlSE)"),"#N/A") -> #N/A | AZ9: =IFERROR(__xludf.DUMMYFUNCTION("vlookup(BB9,importrange(""https://docs.google.com/spreadsheets/d/1d2vevQ_7D_v35q4wCQ4RpQ_IPoTwEMB9Yp6ymwlPqew/edit?gid=984458430#gid=984458430"", ""'replication success'!A:M""), 12, FAlSE)"),"#N/A") -> #N/A | BA9: =IFERROR(__xludf.DUMMYFUNCTION("vlookup(BB9,importrange(""https://docs.google.com/spreadsheets/d/1d2vevQ_7D_v35q4wCQ4RpQ_IPoTwEMB9Yp6ymwlPqew/edit?gid=984458430#gid=984458430"", ""'replication success'!A:M""), 13, FAlSE)"),"#N/A") -> #N/A | BB9: =IFERROR(__xludf.DUMMYFUNCTION("REGEXREPLACE(G9, ""_[a-z]{1,2}$"", """")"),"7vgkq") -> 7vgkq | BD9: LR
A10: 10 | B10: validated - discarded | C10: double | D10: Nikolay | F10: acykd_1 | G10: acykd | H10: Nikolay Petrov | I10: 45639 | K10: original sample size is 42, but 1 was excluded afterwards (p. 137) | L10: - Please type "NA" if you could not find "regis" in the manuscript. - Good catch with the N = 41! - This is the preregistration: https://osf.io/8urxv It is linked at the top of the entry | M10: Mussweiler, T., & Englich, B. (2005). Subliminal anchoring: Judgmental consequences and underlying mechanisms. Organizational Behavior and Human Decision Processes, 98(2), 133-143. | N10: 10.1016/j.obhdp.2004.12.002 | O10: 2 | P10: =hyperlink(vlookup(lower(N10),'File Links'!A:B, 2, FALSE), SUBSTITUTE(lower(N10), "/", "--") & ".pdf") -> 10.1016--j.obhdp.2004.12.002.pdf | Q10: {=if(iserror(MATCH(V10, 'File Links'!C:C, 0)), "N/A", HYPERLINK(INDEX('File Links'!B:B, MATCH(P10, 'File Links'!C:C, 0))))} -> https://drive.google.com/file/d/1CZ8RmInPe2eqHwf-p8tl0IQxpn8_H_C5/view?usp=drivesdk | R10: Röseler, L., Schütz, A., Burlakovas, E., Dück, M., Fels, S., Janiczek, S., … Seida, C. (2022, September 15). Replication Mussweiler & Englich, 2005, Study 2. https://doi.org/10.17605/OSF.IO/ACYKD | S10: 10.1016/j.jesp.2020.104066 | V10: =hyperlink(vlookup(lower(S10),'File Links'!E:F, 2, FALSE), SUBSTITUTE(lower(S10), "/", "--") & ".pdf") -> 10.1016--j.jesp.2020.104066.pdf | W10: replication | X10: {=if(iserror(MATCH(V10, 'File Links'!C:C, 0)), "N/A", HYPERLINK(INDEX('File Links'!B:B, MATCH(V10, 'File Links'!C:C, 0))))} -> https://drive.google.com/file/d/1Q7xa-u3DEssueb6fBYD39BjDPub6xcHR/view?usp=drivesdk | Z10: Judgment and Decision Making | AA10: subliminal anchoring | AB10: anchoring, subliminal priming, judgment bias, decision-making | AC10: estimates for numeric judgments are assimilated toward anchor values, even when these anchors are presented subliminally and outside of conscious awareness | AD10: Participants who were presented with the high anchor value estimated the car price to be higher (M = 21,219 Euro) than those presented with the low anchor value (M = 17,150 Euro), t(39) = 2.02, p < .05, r = .31. | AE10: 137 | AF10: 41 | AG10: 0.31 | AH10: r | AI10: p. 137 | AJ10: 0.05 | AK10: l (<) | AL10: NA (not reported) | AM10: no | AN10: NA | AO10: 165 | AP10: -0.148 | AQ10: d | AR10: p. 3 | AS10: 0.83 | AT10: e (=) | AU10: 1 (one) | AV10: no | AW10: https://pdf.sciencedirectassets.com/272387/1-s2.0-S0022103120X00060/1-s2.0-S0022103120304066/main.pdf?X-Amz-Security-Token=IQoJb3JpZ2luX2VjEBgaCXVzLWVhc3QtMSJGMEQCICnHJqcNsP62IhJ5t%2BlQbccPwseA76qFfK6Rgkom8dtRAiB1LS%2BiM%2B0b%2BvwiyOom715iyNnHeXVQbXmSm95pdglacyq8BQjR%2F%2F%2F%2F%2F%2F%2F%2F%2F%2F8BEAUaDDA1OTAwMzU0Njg2NSIMmoze3y0Q1yERk%2B0lKpAF0gYTSXrqATr%2FlouJQrzfzrF%2B%2BHvghuPve%2FIY6N1xxaQBobJn18bDe0NKhRM4T2mvBEFjCOaVSqmUoM3%2F%2BmGL%2BTAQq6mB%2F5aQpDiqXVVnBGSq5%2F03UsrB78W9ZYcX3HuqmMRCwLpHPAIgIHd9zQtRRFGwk6RR%2ByNdrZ7EqjeWgcIKuyAr9%2Bj0JJ74pqGzqA1bFSaiBMqqZjviAxsq%2FjIO4yKprM2jCQw%2B%2FbZMITGLBdecPGFvQADAleUhJZgsYDQbMSkktZJ6E%2FJW5MtMzDJ3LrlhsdSqiHd28N4%2FJtYL8gNCs%2F9wK3a1s%2BQvM838pcLinkI8unVh1Gcvfxjbq6fYI6x4hCc7UZUEXs%2BEd%2Bo1x9GFvp3tcM%2BwJYlAa%2BEE%2FZcco8Dj58jnqzyOal0dDMeeWOjHL3y8xqwOE69icvonadJhHFVwONEoA1aox7vcITDF0spX53bm8Off4OeJ4bHC6QFHjIgBmUnwwVhqwcTI1CofN%2BPxww0zY3oNg4NrIO%2B5IVffRucPE9pztEeVHOdsmVPWyRlEFrjQ3aVJiYpL6TVfW3VfFLrAFifjveRxLAGB28CYsVXmTUz0Qxq6JRu7SlmaRNP2YnG7ipXXbiuZbwrorkm%2BxDc3uzBAI3Z82HTq1%2FmzxXw3SDN8%2FgQpgwWMXmWr%2F%2BckEKS7a7j2988ql%2B%2Fy%2BqfrHVJ5rVoDXKUgDUP6rR3X1ejf1UZwyc8ja5HXFbPfOefIT%2FsnbjIx3Ff255FID0Z6RGepP7orcagCAcWl7CBXLkbWM%2BaP6Oi1ITpYGOPrwvSeRMyKPH2NmAiiWZE5l0m%2FTJGJ0tND%2FrcK%2BOlvjkyuEOx33q4BZeSRwvKBTPBeeTtjgd9K%2BGRMok%2Fe5xEw28zvugY6sgH0sfyibldLqTratcbSkw7B9kA7YzvSU7Iyhc8zjvj18adk0B6r39A2zAda5VndB8QXUitJ8361WDPVPzGMTek%2Fl5bziH%2FtLRb2uo30VQ5T74JJWTp8l6Rs7L5pQAvE%2FQTclPBuc%2BZrz7CkEfVLz%2FJt0xicBVpzawZjnQzXuFBfBBbMr%2FWdBHYYpRqC6jMqh3zJIYsu9ZeQkzwiXFbF14t%2BITCuLmhK4klb9H3%2BQ4iKcUaK&X-Amz-Algorithm=AWS4-HMAC-SHA256&X-Amz-Date=20241213T084150Z&X-Amz-SignedHeaders=host&X-Amz-Expires=300&X-Amz-Credential=ASIAQ3PHCVTYUWRHKPES%2F20241213%2Fus-east-1%2Fs3%2Faws4_request&X-Amz-Signature=33924dc8199c3da89949ad504da4000be209df455000e1a7e4fee4140f60b1b1&hash=6979ab83d6e022fd52840830bb00b033291cf8235f9e721ac49f027cf55e995c&host=68042c943591013ac2b2430a89b270f6af2c76d8dfd086a07176afe7c76c2c61&pii=S0022103120304066&tid=spdf-0273d28f-03b4-4283-8694-d21fc2577d91&sid=18412b78662c794bb67b6200a74126f2bac9gxrqb&type=client&tsoh=d3d3LnNjaWVuY2VkaXJlY3QuY29t&ua=010859005455035b5a&rr=8f14a84b18840c73&cc=bg#link_ir0025 | AX10: 2 - close | AY10: =IFERROR(__xludf.DUMMYFUNCTION("vlookup(BB10,importrange(""https://docs.google.com/spreadsheets/d/1d2vevQ_7D_v35q4wCQ4RpQ_IPoTwEMB9Yp6ymwlPqew/edit?gid=984458430#gid=984458430"", ""'replication success'!A:K""), 11, FAlSE)"),"failed") -> failed | AZ10: =IFERROR(__xludf.DUMMYFUNCTION("vlookup(BB10,importrange(""https://docs.google.com/spreadsheets/d/1d2vevQ_7D_v35q4wCQ4RpQ_IPoTwEMB9Yp6ymwlPqew/edit?gid=984458430#gid=984458430"", ""'replication success'!A:M""), 12, FAlSE)"),"To sum up, due to the extremely high power, the anchoring effect should have occurred if it indeed existed. We interpret the fact that there was no sign of anchoring—even after we excluded outliers and controlled for whether participants saw the flicke"&"ring—as inconsistent with the claim that subliminal anchoring exists.") -> To sum up, due to the extremely high power, the anchoring effect should have occurred if it indeed existed. We interpret the fact that there was no sign of anchoring—even after we excluded outliers and controlled for whether participants saw the flickering—as inconsistent with the claim that subliminal anchoring exists. | BA10: =IFERROR(__xludf.DUMMYFUNCTION("vlookup(BB10,importrange(""https://docs.google.com/spreadsheets/d/1d2vevQ_7D_v35q4wCQ4RpQ_IPoTwEMB9Yp6ymwlPqew/edit?gid=984458430#gid=984458430"", ""'replication success'!A:M""), 13, FAlSE)"),"pg.3") -> pg.3 | BB10: =IFERROR(__xludf.DUMMYFUNCTION("REGEXREPLACE(G10, ""_[a-z]{1,2}$"", """")"),"acykd") -> acykd | BC10: - Please type "NA" if you could not find "regis" in the manuscript. - Good catch with the N = 41! - This is the preregistration: https://osf.io/8urxv It is linked at the top of the entry | BD10: LR
A11: 11 | B11: validated - chosen | C11: double | D11: Hakile | F11: acykd_1 | G11: acykd | H11: Hakile Resulbegoviq | I11: 45641 | J11: 45663 | K11: informative failure to replicate | L11: updated reference_r to report instead of the OSF page | M11: Mussweiler, T., & Englich, B. (2005). Subliminal anchoring: Judgmental consequences and underlying mechanisms. Organizational Behavior and Human Decision Processes, 98(2), 133-143. | N11: 10.1016/j.obhdp.2004.12.002 | O11: 2 | P11: =hyperlink(vlookup(lower(N11),'File Links'!A:B, 2, FALSE), SUBSTITUTE(lower(N11), "/", "--") & ".pdf") -> 10.1016--j.obhdp.2004.12.002.pdf | Q11: {=if(iserror(MATCH(V11, 'File Links'!C:C, 0)), "N/A", HYPERLINK(INDEX('File Links'!B:B, MATCH(P11, 'File Links'!C:C, 0))))} -> https://drive.google.com/file/d/1CZ8RmInPe2eqHwf-p8tl0IQxpn8_H_C5/view?usp=drivesdk | R11: Röseler, L., Schütz, A., Blank, P. A., Dück, M., Fels, S., Kupfer, J., ... & Seida, C. (2021). Evidence against subliminal anchoring: Two close, highly powered, preregistered, and failed replication attempts. Journal of Experimental Social Psychology, 92, 104066. https://doi.org/10.1016/j.jesp.2020.104066 | S11: 10.1016/j.jesp.2020.104066 | U11: 1 | V11: =hyperlink(vlookup(lower(S11),'File Links'!E:F, 2, FALSE), SUBSTITUTE(lower(S11), "/", "--") & ".pdf") -> 10.1016--j.jesp.2020.104066.pdf | W11: Replication | X11: {=if(iserror(MATCH(V11, 'File Links'!C:C, 0)), "N/A", HYPERLINK(INDEX('File Links'!B:B, MATCH(V11, 'File Links'!C:C, 0))))} -> https://drive.google.com/file/d/1Q7xa-u3DEssueb6fBYD39BjDPub6xcHR/view?usp=drivesdk | Z11: Social Psychology | AA11: Subliminal anchoring | AB11: Anchoring; Heuristics; Comparison; Selective accessibility; Assimilation | AC11: Subliminally presented numerical anchors influence judgment, causing estimates to shift toward the anchor values without participants being consciously aware of the anchors. | AD11: Participants who were presented with the high anchor value estimated the car price to be higher (M = 21,219 Euro) than those presented with the low anchor value (M = 17,150 Euro), t(39) = 2.02, p < .05, r = .31. | AE11: 137 | AF11: 41 | AG11: 0.31 | AH11: r | AI11: p. 137 | AJ11: 0.05 | AK11: l (<) | AL11: NA (not reported) | AM11: no | AN11: NA | AO11: 165 | AP11: -0.148 | AQ11: d | AR11: p. 3 | AS11: 0.83 | AT11: e (=) | AU11: 1 (one) | AV11: no | AW11: https://osf.io/8urxv | AX11: 2 - close | AY11: =IFERROR(__xludf.DUMMYFUNCTION("vlookup(BB11,importrange(""https://docs.google.com/spreadsheets/d/1d2vevQ_7D_v35q4wCQ4RpQ_IPoTwEMB9Yp6ymwlPqew/edit?gid=984458430#gid=984458430"", ""'replication success'!A:K""), 11, FAlSE)"),"failed") -> failed | AZ11: =IFERROR(__xludf.DUMMYFUNCTION("vlookup(BB11,importrange(""https://docs.google.com/spreadsheets/d/1d2vevQ_7D_v35q4wCQ4RpQ_IPoTwEMB9Yp6ymwlPqew/edit?gid=984458430#gid=984458430"", ""'replication success'!A:M""), 12, FAlSE)"),"To sum up, due to the extremely high power, the anchoring effect should have occurred if it indeed existed. We interpret the fact that there was no sign of anchoring—even after we excluded outliers and controlled for whether participants saw the flicke"&"ring—as inconsistent with the claim that subliminal anchoring exists.") -> To sum up, due to the extremely high power, the anchoring effect should have occurred if it indeed existed. We interpret the fact that there was no sign of anchoring—even after we excluded outliers and controlled for whether participants saw the flickering—as inconsistent with the claim that subliminal anchoring exists. | BA11: =IFERROR(__xludf.DUMMYFUNCTION("vlookup(BB11,importrange(""https://docs.google.com/spreadsheets/d/1d2vevQ_7D_v35q4wCQ4RpQ_IPoTwEMB9Yp6ymwlPqew/edit?gid=984458430#gid=984458430"", ""'replication success'!A:M""), 13, FAlSE)"),"pg.3") -> pg.3 | BB11: =IFERROR(__xludf.DUMMYFUNCTION("REGEXREPLACE(G11, ""_[a-z]{1,2}$"", """")"),"acykd") -> acykd | BC11: Feedback for Hakile: - The degreees of freedom for the t test are 39, indicating that N = 41 - the number of tails was actually not reported (it does not say anywhere whether it is one-tailed or two-tailed but was coded as 2) - I could not find the d = 0.71 on p. 137 or anywhere in the manuscript. - Please type "NA" if you could not find "regis" in the manuscript. - Please rather use text for the claim that includes statistical elements, such as the effect on p. 137 under "results and discussion" - This is the preregistration: https://osf.io/8urxv It is linked at the top of the entry. You linked the "post completion" registration. | BD11: LR
A12: 12 | B12: validated - chosen | C12: double | D12: Sarah | F12: additional_studies1_1 | G12: additional_studies1_a | H12: SAJ | I12: 45427 | J12: 45624 | M12: Rellensmann, J., & Schukajlow, S. (2017). Does students’ interest in a mathematical problem depend on the problem’s connection to reality? An analysis of students’ interest and pre-service teachers’ judgments of students’ interest in problems with and without a connection to reality. ZDM, 49, 367-378. https://doi.org/10.1007/s11858-016-0819-3 | N12: 10.1007/s11858-016-0819-3 | O12: 1 | P12: =hyperlink(vlookup(lower(N12),'File Links'!A:B, 2, FALSE), SUBSTITUTE(lower(N12), "/", "--") & ".pdf") -> 10.1007--s11858-016-0819-3.pdf | Q12: {=if(iserror(MATCH(V12, 'File Links'!C:C, 0)), "N/A", HYPERLINK(INDEX('File Links'!B:B, MATCH(P12, 'File Links'!C:C, 0))))} -> https://drive.google.com/file/d/1A3A0XWewbvFp536VbiCjIAYxdIJwVP-9/view?usp=drivesdk | R12: García-Cerdá, C., Segura, C., & Ferrando, I. (2024). Influence of the Type of Mathematical Problems on Students’ and Pre-service Teachers’ Interest and Performance. A Replication and Elaboration Study. Implementation and Replication Studies in Mathematics Education, 1(aop), 1-35. https://doi.org/10.1163/26670127-bja10017 | S12: 10.1163/26670127-bja10017 | U12: 1 | V12: =hyperlink(vlookup(lower(S12),'File Links'!E:F, 2, FALSE), SUBSTITUTE(lower(S12), "/", "--") & ".pdf") -> 10.1163--26670127-bja10017.pdf | W12: Title - "A replication and elaboration study" Abstract - "... the process of conceptual replication of Rellensmann and Schukajlow’s (2017) research..." | X12: {=if(iserror(MATCH(V12, 'File Links'!C:C, 0)), "N/A", HYPERLINK(INDEX('File Links'!B:B, MATCH(V12, 'File Links'!C:C, 0))))} -> https://drive.google.com/file/d/1u_oSZ0fEx8q87XxieN1axHREEr_kiGBE/view?usp=drivesdk | Z12: Education | AA12: interest in mathematics | AB12: mathematics, interest, students, pre-service teachers, diagnostic competence, real-world problems, performance, problem-solving | AC12: Influence of the Type of Mathematical Problems on Students’ Interest | AD12: A t-test for dependent samples indicated that the difference in students’ interest in the two problem types was statistically significant [t(99) = −2.96, p < 0.01]. | AE12: 7 | AF12: 100 | AG12: 0.3 | AH12: d | AI12: p. 7 | AJ12: 0.01 | AK12: l (<) | AL12: NA (not reported) | AM12: yes | AN12: NA | AO12: 80 | AP12: X2(2) = 9.99 | AQ12: test statistic | AR12: preprint p. 22 Kendells W = X2/N(K-1), X2 = 9.99, N = 80, K = 3 W = 9.99/ (80*(3-1)), W = 9.99/ (160), W ~ 0.06 | AS12: 0.01 | AT12: l (<) | AU12: NA (not reported) | AV12: no | AW12: NA | AX12: 2 - close | AY12: =IFERROR(__xludf.DUMMYFUNCTION("vlookup(BB12,importrange(""https://docs.google.com/spreadsheets/d/1d2vevQ_7D_v35q4wCQ4RpQ_IPoTwEMB9Yp6ymwlPqew/edit?gid=984458430#gid=984458430"", ""'replication success'!A:K""), 11, FAlSE)"),"successful") -> successful | AZ12: =IFERROR(__xludf.DUMMYFUNCTION("vlookup(BB12,importrange(""https://docs.google.com/spreadsheets/d/1d2vevQ_7D_v35q4wCQ4RpQ_IPoTwEMB9Yp6ymwlPqew/edit?gid=984458430#gid=984458430"", ""'replication success'!A:M""), 12, FAlSE)"),"This result is consistent with the replicated study (Rellensmann & Schukajlow, 2017), although, in that study, the interest values were adjusted to control the effect of task difficulty (in the present work that part corresponds to the study of perform"&"ance that will be discussed later).") -> This result is consistent with the replicated study (Rellensmann & Schukajlow, 2017), although, in that study, the interest values were adjusted to control the effect of task difficulty (in the present work that part corresponds to the study of performance that will be discussed later). | BA12: =IFERROR(__xludf.DUMMYFUNCTION("vlookup(BB12,importrange(""https://docs.google.com/spreadsheets/d/1d2vevQ_7D_v35q4wCQ4RpQ_IPoTwEMB9Yp6ymwlPqew/edit?gid=984458430#gid=984458430"", ""'replication success'!A:M""), 13, FAlSE)"),"pg.26") -> pg.26 | BB12: =IFERROR(__xludf.DUMMYFUNCTION("REGEXREPLACE(G12, ""_[a-z]{1,2}$"", """")"),"additional_studies1") -> additional_studies1 | BD12: LR
A13: 13 | B13: validated - discarded | C13: double | D13: Alexsandr | F13: additional_studies1_1 | G13: additional_studies1_a | H13: Aleksandr Pravednikov | I13: 45427 | J13: 45625 | K13: Claim text_r We observe that, in terms of means, there are no great differences in interest according to the type of problem. For students intramathematical problems were the most interesting (Mi = 2.77, SDi = 1.25), followed by word problems (Mw = 2.75, SDw = 1.18), and finally by modelling problems (Mm = 2.66, SDm = 1.26). - Table 1. To analyse whether the differences are significant, a hypothesis test was performed. Given that the means of interest did not follow, according to the results of the Shapiro-Wilk test, a normal distribution in any of the three types of problems, we applied Friedman’s non-parametric test. Thus, we obtained that there were differences between at least two types of problems (𝜒𝜒2(2)=9.99, p < 0.01). A post hoc analysis, using the Nemenyi test, ensured that there were significant differences in task-specific interest between word and modelling problems (p < 0.05), but not between the other combinations. [...] Page 21-22 | M13: Rellensmann, J., & Schukajlow, S. (2017). Does students’ interest in a mathematical problem depend on the problem’s connection to reality? An analysis of students’ interest and pre-service teachers’ judgments of students’ interest in problems with and without a connection to reality. ZDM, 49, 367-378. https://doi.org/10.1007/s11858-016-0819-3 | N13: 10.1007/s11858-016-0819-3 | P13: =hyperlink(vlookup(lower(N13),'File Links'!A:B, 2, FALSE), SUBSTITUTE(lower(N13), "/", "--") & ".pdf") -> 10.1007--s11858-016-0819-3.pdf | Q13: {=if(iserror(MATCH(V13, 'File Links'!C:C, 0)), "N/A", HYPERLINK(INDEX('File Links'!B:B, MATCH(P13, 'File Links'!C:C, 0))))} -> https://drive.google.com/file/d/1A3A0XWewbvFp536VbiCjIAYxdIJwVP-9/view?usp=drivesdk | R13: García-Cerdá, C., Segura, C., & Ferrando, I. (2024). Influence of the Type of Mathematical Problems on Students’ and Pre-service Teachers’ Interest and Performance. A Replication and Elaboration Study. Implementation and Replication Studies in Mathematics Education, 1(aop), 1-35. https://doi.org/10.1163/26670127-bja10017 | S13: 10.1163/26670127-bja10017 | V13: =hyperlink(vlookup(lower(S13),'File Links'!E:F, 2, FALSE), SUBSTITUTE(lower(S13), "/", "--") & ".pdf") -> 10.1163--26670127-bja10017.pdf | X13: {=if(iserror(MATCH(V13, 'File Links'!C:C, 0)), "N/A", HYPERLINK(INDEX('File Links'!B:B, MATCH(V13, 'File Links'!C:C, 0))))} -> https://drive.google.com/file/d/1u_oSZ0fEx8q87XxieN1axHREEr_kiGBE/view?usp=drivesdk | Z13: Educational Sciences | AB13: Students | AC13: Influence of the Type of Mathematical Problems on Students’ and Pre-service Teachers’ Interest and Performance | AD13: Students reported a mean level of interest of Madj = 2.71 (SDadj = 0.90) in solving problems with a connection to reality and Madj = 2.91 (SDadj = 1.00) in solving problems without a connection to reality when the impact of task difficulty was controlled for (Table 2). Means and standard errors for students’ interest are graphically displayed in Fig. 4. A t-test for dependent samples indicated that the difference in students’ interest in the two problem types was statistically significant [t(99) = −2.96, p < 0.01]. Cohen’s d = 0.30 indicated a small effect. This means that, contrary to our expectations, students reported more interest in solving problems without a connection to reality thann in problems with a connection to reality. | AE13: 7(373) | AF13: 100 | AG13: 0.3 | AH13: d | AJ13: 0.01 | AK13: l (<) | AL13: NA (not reported) | AN13: NA | AO13: 80 | AS13: p < 0.05 | AT13: l (<) | AU13: NA (not reported) | AX13: 2 - close | AY13: =IFERROR(__xludf.DUMMYFUNCTION("vlookup(BB13,importrange(""https://docs.google.com/spreadsheets/d/1d2vevQ_7D_v35q4wCQ4RpQ_IPoTwEMB9Yp6ymwlPqew/edit?gid=984458430#gid=984458430"", ""'replication success'!A:K""), 11, FAlSE)"),"successful") -> successful | AZ13: =IFERROR(__xludf.DUMMYFUNCTION("vlookup(BB13,importrange(""https://docs.google.com/spreadsheets/d/1d2vevQ_7D_v35q4wCQ4RpQ_IPoTwEMB9Yp6ymwlPqew/edit?gid=984458430#gid=984458430"", ""'replication success'!A:M""), 12, FAlSE)"),"This result is consistent with the replicated study (Rellensmann & Schukajlow, 2017), although, in that study, the interest values were adjusted to control the effect of task difficulty (in the present work that part corresponds to the study of perform"&"ance that will be discussed later).") -> This result is consistent with the replicated study (Rellensmann & Schukajlow, 2017), although, in that study, the interest values were adjusted to control the effect of task difficulty (in the present work that part corresponds to the study of performance that will be discussed later). | BA13: =IFERROR(__xludf.DUMMYFUNCTION("vlookup(BB13,importrange(""https://docs.google.com/spreadsheets/d/1d2vevQ_7D_v35q4wCQ4RpQ_IPoTwEMB9Yp6ymwlPqew/edit?gid=984458430#gid=984458430"", ""'replication success'!A:M""), 13, FAlSE)"),"pg.26") -> pg.26 | BB13: =IFERROR(__xludf.DUMMYFUNCTION("REGEXREPLACE(G13, ""_[a-z]{1,2}$"", """")"),"additional_studies1") -> additional_studies1 | BD13: LR
A14: 14 | B14: validated - chosen | C14: double | D14: Sarah | F14: additional_studies1_1 | G14: additional_studies1_b | H14: SAJ | I14: 45427 | J14: 45624 | K14: this effect was not explored in the original paper | M14: Rellensmann, J., & Schukajlow, S. (2017). Does students’ interest in a mathematical problem depend on the problem’s connection to reality? An analysis of students’ interest and pre-service teachers’ judgments of students’ interest in problems with and without a connection to reality. ZDM, 49, 367-378. https://doi.org/10.1007/s11858-016-0819-3 | N14: 10.1007/s11858-016-0819-3 | O14: 1 | P14: =hyperlink(vlookup(lower(N14),'File Links'!A:B, 2, FALSE), SUBSTITUTE(lower(N14), "/", "--") & ".pdf") -> 10.1007--s11858-016-0819-3.pdf | Q14: {=if(iserror(MATCH(V14, 'File Links'!C:C, 0)), "N/A", HYPERLINK(INDEX('File Links'!B:B, MATCH(P14, 'File Links'!C:C, 0))))} -> https://drive.google.com/file/d/1A3A0XWewbvFp536VbiCjIAYxdIJwVP-9/view?usp=drivesdk | R14: García-Cerdá, C., Segura, C., & Ferrando, I. (2024). Influence of the Type of Mathematical Problems on Students’ and Pre-service Teachers’ Interest and Performance. A Replication and Elaboration Study. Implementation and Replication Studies in Mathematics Education, 1(aop), 1-35. https://doi.org/10.1163/26670127-bja10017 | S14: 10.1163/26670127-bja10017 | U14: 1 | V14: =hyperlink(vlookup(lower(S14),'File Links'!E:F, 2, FALSE), SUBSTITUTE(lower(S14), "/", "--") & ".pdf") -> 10.1163--26670127-bja10017.pdf | W14: Title - "A replication and elaboration study" Abstract - "... the process of conceptual replication of Rellensmann and Schukajlow’s (2017) research..." | X14: {=if(iserror(MATCH(V14, 'File Links'!C:C, 0)), "N/A", HYPERLINK(INDEX('File Links'!B:B, MATCH(V14, 'File Links'!C:C, 0))))} -> https://drive.google.com/file/d/1u_oSZ0fEx8q87XxieN1axHREEr_kiGBE/view?usp=drivesdk | Z14: Education | AA14: interest in mathematics | AB14: mathematics, interest, students, pre-service teachers, diagnostic competence, real-world problems, performance, problem-solving | AC14: Influence of the Type of Mathematical Problems on Pre-service Teachers’ Interest | AD14: A t-test for dependent samples showed a significant difference in pre-service teachers’ judgments of students’ interest in solving the two types of problems [t(162) = 14.33, p < 0.01]. Cohen’s d = 1.12 | AE14: 7 | AF14: 163 | AG14: 1.12 | AH14: d | AI14: p. 7 | AJ14: 0.01 | AK14: l (<) | AL14: NA (not reported) | AM14: yes | AN14: NA | AO14: 80 | AP14: X2(2) = 16.54 | AQ14: test statistic | AR14: Kendells W = X2/N(K-1), X2 = 16.54, N = 80, K = 3 W = 16.54/ (80*(3-1)), W = 16.54/ (160), W ~ 0.1 | AS14: 0.01 | AT14: l (<) | AU14: NA (not reported) | AV14: no | AW14: NA | AX14: 2 - close | AY14: =IFERROR(__xludf.DUMMYFUNCTION("vlookup(BB14,importrange(""https://docs.google.com/spreadsheets/d/1d2vevQ_7D_v35q4wCQ4RpQ_IPoTwEMB9Yp6ymwlPqew/edit?gid=984458430#gid=984458430"", ""'replication success'!A:K""), 11, FAlSE)"),"successful") -> successful | AZ14: =IFERROR(__xludf.DUMMYFUNCTION("vlookup(BB14,importrange(""https://docs.google.com/spreadsheets/d/1d2vevQ_7D_v35q4wCQ4RpQ_IPoTwEMB9Yp6ymwlPqew/edit?gid=984458430#gid=984458430"", ""'replication success'!A:M""), 12, FAlSE)"),"This result is consistent with the replicated study (Rellensmann & Schukajlow, 2017), although, in that study, the interest values were adjusted to control the effect of task difficulty (in the present work that part corresponds to the study of perform"&"ance that will be discussed later).") -> This result is consistent with the replicated study (Rellensmann & Schukajlow, 2017), although, in that study, the interest values were adjusted to control the effect of task difficulty (in the present work that part corresponds to the study of performance that will be discussed later). | BA14: =IFERROR(__xludf.DUMMYFUNCTION("vlookup(BB14,importrange(""https://docs.google.com/spreadsheets/d/1d2vevQ_7D_v35q4wCQ4RpQ_IPoTwEMB9Yp6ymwlPqew/edit?gid=984458430#gid=984458430"", ""'replication success'!A:M""), 13, FAlSE)"),"pg.26") -> pg.26 | BB14: =IFERROR(__xludf.DUMMYFUNCTION("REGEXREPLACE(G14, ""_[a-z]{1,2}$"", """")"),"additional_studies1") -> additional_studies1 | BD14: LR
A15: 15 | B15: validated - discarded | C15: double | D15: Alexsandr | F15: additional_studies1_1 | G15: additional_studies1_b | H15: Aleksandr Pravednikov | I15: 45427 | J15: 45625 | K15: Claim text_r Table 2 shows the average situational interest of 80 pre-service teachers according to the connection to the reality of the problems. We observe that, for pre-service teachers, word problems were the most interesting (Mw = 3.28, SDw = 1.22), followed by modelling problems (Mm = 3.11, SDm = 1.25) and, finally, intramathematical problems (Mi = 2.92, SDi = 1.24). Again, we conducted a hypothesis test to analyse whether there were significant differences in interest according to the connection with the reality of the problems. The means of interest did not follow a normal distribution either, so we obtained that there are significant differences between at least two types of problems (𝜒𝜒2(2)=16.54, p < 0.01) by applying Friedman’s test. Nemenyi’s test ensured that there were significant differences in task-specific interest between word and modelling problems (p < 0.05), and between intramathematical and word problems (p < 0.01). There were no significant differences between intramathematical and modelling problems (p = 0.46), indicating that word problems were significantly more interesting for pre-service teachers. [...] Page 22-23 | M15: Rellensmann, J., & Schukajlow, S. (2017). Does students’ interest in a mathematical problem depend on the problem’s connection to reality? An analysis of students’ interest and pre-service teachers’ judgments of students’ interest in problems with and without a connection to reality. ZDM, 49, 367-378. https://doi.org/10.1007/s11858-016-0819-3 | N15: 10.1007/s11858-016-0819-3 | P15: =hyperlink(vlookup(lower(N15),'File Links'!A:B, 2, FALSE), SUBSTITUTE(lower(N15), "/", "--") & ".pdf") -> 10.1007--s11858-016-0819-3.pdf | Q15: {=if(iserror(MATCH(V15, 'File Links'!C:C, 0)), "N/A", HYPERLINK(INDEX('File Links'!B:B, MATCH(P15, 'File Links'!C:C, 0))))} -> https://drive.google.com/file/d/1A3A0XWewbvFp536VbiCjIAYxdIJwVP-9/view?usp=drivesdk | R15: García-Cerdá, C., Segura, C., & Ferrando, I. (2024). Influence of the Type of Mathematical Problems on Students’ and Pre-service Teachers’ Interest and Performance. A Replication and Elaboration Study. Implementation and Replication Studies in Mathematics Education, 1(aop), 1-35. https://doi.org/10.1163/26670127-bja10017 | S15: 10.1163/26670127-bja10017 | V15: =hyperlink(vlookup(lower(S15),'File Links'!E:F, 2, FALSE), SUBSTITUTE(lower(S15), "/", "--") & ".pdf") -> 10.1163--26670127-bja10017.pdf | X15: {=if(iserror(MATCH(V15, 'File Links'!C:C, 0)), "N/A", HYPERLINK(INDEX('File Links'!B:B, MATCH(V15, 'File Links'!C:C, 0))))} -> https://drive.google.com/file/d/1u_oSZ0fEx8q87XxieN1axHREEr_kiGBE/view?usp=drivesdk | Z15: Educational Sciences | AB15: Pre-service teachers | AC15: Influence of the Type of Mathematical Problems on Students’ and Pre-service Teachers’ Interest and Performance | AD15: Pre-service teachers predicted a mean of Madj = 3.18 (SDadj = 0.48) for students’ interest in problems with a connection to reality and Madj = 2.47 (SDadj = 0.60) for their interest in problems without a connection to reality (Table 2). Means and standard errors for pre-service teachers’ judgments are also graphically displayed in Fig. 4. A t-test for dependent samples showed a significant difference in pre-service teachers’ judgments of students’ interest in solving the two types of problems [t(162) = 14.33, p < 0.01]. Cohen’s d = 1.12 indicated a large effect. As hypothesized, this means that pre-service teachers believed that solving problems with a connection to reality triggered more interest in students than solving problems without a connection to reality. | AE15: 7(373) | AF15: 163 | AG15: 1.12 | AH15: d | AJ15: 0.01 | AK15: l (<) | AL15: NA (not reported) | AN15: NA | AO15: 80 | AS15: p < 0.01 | AT15: l (<) | AU15: NA (not reported) | AX15: 2 - close | AY15: =IFERROR(__xludf.DUMMYFUNCTION("vlookup(BB15,importrange(""https://docs.google.com/spreadsheets/d/1d2vevQ_7D_v35q4wCQ4RpQ_IPoTwEMB9Yp6ymwlPqew/edit?gid=984458430#gid=984458430"", ""'replication success'!A:K""), 11, FAlSE)"),"successful") -> successful | AZ15: =IFERROR(__xludf.DUMMYFUNCTION("vlookup(BB15,importrange(""https://docs.google.com/spreadsheets/d/1d2vevQ_7D_v35q4wCQ4RpQ_IPoTwEMB9Yp6ymwlPqew/edit?gid=984458430#gid=984458430"", ""'replication success'!A:M""), 12, FAlSE)"),"This result is consistent with the replicated study (Rellensmann & Schukajlow, 2017), although, in that study, the interest values were adjusted to control the effect of task difficulty (in the present work that part corresponds to the study of perform"&"ance that will be discussed later).") -> This result is consistent with the replicated study (Rellensmann & Schukajlow, 2017), although, in that study, the interest values were adjusted to control the effect of task difficulty (in the present work that part corresponds to the study of performance that will be discussed later). | BA15: =IFERROR(__xludf.DUMMYFUNCTION("vlookup(BB15,importrange(""https://docs.google.com/spreadsheets/d/1d2vevQ_7D_v35q4wCQ4RpQ_IPoTwEMB9Yp6ymwlPqew/edit?gid=984458430#gid=984458430"", ""'replication success'!A:M""), 13, FAlSE)"),"pg.26") -> pg.26 | BB15: =IFERROR(__xludf.DUMMYFUNCTION("REGEXREPLACE(G15, ""_[a-z]{1,2}$"", """")"),"additional_studies1") -> additional_studies1 | BD15: LR
A16: 16 | B16: validated - discarded | C16: double | D16: Sarah | F16: additional_studies1_1 | G16: additional_studies1_c | H16: SAJ | I16: 45427 | J16: 45624 | K16: this effect was not explored in the original paper | L16: discarded because this is an extension that cannot be paired up with an original finding | M16: Rellensmann, J., & Schukajlow, S. (2017). Does students’ interest in a mathematical problem depend on the problem’s connection to reality? An analysis of students’ interest and pre-service teachers’ judgments of students’ interest in problems with and without a connection to reality. ZDM, 49, 367-378. https://doi.org/10.1007/s11858-016-0819-3 | N16: 10.1007/s11858-016-0819-3 | O16: 1 | P16: =hyperlink(vlookup(lower(N16),'File Links'!A:B, 2, FALSE), SUBSTITUTE(lower(N16), "/", "--") & ".pdf") -> 10.1007--s11858-016-0819-3.pdf | Q16: {=if(iserror(MATCH(V16, 'File Links'!C:C, 0)), "N/A", HYPERLINK(INDEX('File Links'!B:B, MATCH(P16, 'File Links'!C:C, 0))))} -> https://drive.google.com/file/d/1A3A0XWewbvFp536VbiCjIAYxdIJwVP-9/view?usp=drivesdk | R16: García-Cerdá, C., Segura, C., & Ferrando, I. (2024). Influence of the Type of Mathematical Problems on Students’ and Pre-service Teachers’ Interest and Performance. A Replication and Elaboration Study. Implementation and Replication Studies in Mathematics Education, 1(aop), 1-35. https://doi.org/10.1163/26670127-bja10017 | S16: 10.1163/26670127-bja10017 | U16: 1 | V16: =hyperlink(vlookup(lower(S16),'File Links'!E:F, 2, FALSE), SUBSTITUTE(lower(S16), "/", "--") & ".pdf") -> 10.1163--26670127-bja10017.pdf | W16: Title - "A replication and elaboration study" Abstract - "... the process of conceptual replication of Rellensmann and Schukajlow’s (2017) research..." | X16: {=if(iserror(MATCH(V16, 'File Links'!C:C, 0)), "N/A", HYPERLINK(INDEX('File Links'!B:B, MATCH(V16, 'File Links'!C:C, 0))))} -> https://drive.google.com/file/d/1u_oSZ0fEx8q87XxieN1axHREEr_kiGBE/view?usp=drivesdk | Z16: Education | AA16: interest in mathematics | AB16: mathematics, interest, students, pre-service teachers, diagnostic competence, real-world problems, performance, problem-solving | AC16: Influence of the Type of Mathematical Problems on Student Performance | AN16: NA | AO16: 80 | AP16: 0.27 | AQ16: kendall's w | AR16: Kendells W = X2/N(K-1), X2 = 43.61, N = 80, K = 3 W = 43.61/ (80*(3-1)), W = 43.61/ (160), W ~ 0.27 | AS16: p < 0.01 | AT16: l (<) | AU16: NA (not reported) | AX16: extension | AY16: =IFERROR(__xludf.DUMMYFUNCTION("vlookup(BB16,importrange(""https://docs.google.com/spreadsheets/d/1d2vevQ_7D_v35q4wCQ4RpQ_IPoTwEMB9Yp6ymwlPqew/edit?gid=984458430#gid=984458430"", ""'replication success'!A:K""), 11, FAlSE)"),"successful") -> successful | AZ16: =IFERROR(__xludf.DUMMYFUNCTION("vlookup(BB16,importrange(""https://docs.google.com/spreadsheets/d/1d2vevQ_7D_v35q4wCQ4RpQ_IPoTwEMB9Yp6ymwlPqew/edit?gid=984458430#gid=984458430"", ""'replication success'!A:M""), 12, FAlSE)"),"This result is consistent with the replicated study (Rellensmann & Schukajlow, 2017), although, in that study, the interest values were adjusted to control the effect of task difficulty (in the present work that part corresponds to the study of perform"&"ance that will be discussed later).") -> This result is consistent with the replicated study (Rellensmann & Schukajlow, 2017), although, in that study, the interest values were adjusted to control the effect of task difficulty (in the present work that part corresponds to the study of performance that will be discussed later). | BA16: =IFERROR(__xludf.DUMMYFUNCTION("vlookup(BB16,importrange(""https://docs.google.com/spreadsheets/d/1d2vevQ_7D_v35q4wCQ4RpQ_IPoTwEMB9Yp6ymwlPqew/edit?gid=984458430#gid=984458430"", ""'replication success'!A:M""), 13, FAlSE)"),"pg.26") -> pg.26 | BB16: =IFERROR(__xludf.DUMMYFUNCTION("REGEXREPLACE(G16, ""_[a-z]{1,2}$"", """")"),"additional_studies1") -> additional_studies1 | BD16: LR
