Workbook

Sheet COS coding
F1: id | G1: contributors | H1: date_entered | I1: date_updated | J1: notes_coder | K1: notes_validation | L1: ref_original | M1: doi_original | N1: study_original | Q1: ref_replication | R1: doi_replication | S1: osf_link | T1: study_replication | X1: exclusion | Y1: discipline | Z1: effect | AA1: tags | AB1: description | AC1: claim_text_orig | AD1: claim_text_orig_page | AE1: n_original | AF1: es_orig_value | AG1: es_orig_estype | AI1: pval_value_o | AJ1: pval_type_o | AK1: pval_tails_o | AN1: n_replication | AO1: es_rep_value | AP1: es_rep_estype | AR1: pval_value_r | AS1: pval_type_r | AT1: pval_tails_r
A2: status | B2: approach | C2: coder_1 | D2: coder_2 | E2: entry | F2: id | G2: contributors | H2: date_entered | I2: date_updated | J2: notes_coder | K2: notes_validation | L2: ref_o | M2: doi_o | N2: study_o | O2: file_o | P2: link_o | Q2: ref_r | R2: doi_r | S2: url_r | T2: study_r | U2: file_r | V2: label_r | W2: link_r | X2: exclusion | Y2: discipline | Z2: effect | AA2: tags | AB2: description | AC2: claim_text_o | AD2: claim_page_o | AE2: n_o | AF2: es_value_o | AG2: es_type_o | AH2: es_repr_o | AI2: pval_value_o | AJ2: pval_type_o | AK2: pval_tails_o | AL2: nested_o | AM2: prereg_o | AN2: n_r | AO2: es_value_r | AP2: es_type_r | AQ2: es_repr_r | AR2: pval_value_r | AS2: pval_type_r | AT2: pval_tails_r | AU2: nested_r | AV2: prereg_r | AW2: closeness_r | AX2: feedback_for_coder | AY2: validator
A3: - assigned: the entry has been assigned to a coder - help needed: there is an unresolved conflict - validated - chosen: the entry has been validated and marked as the one to remain in the final dataset - validated - discarded: the entry has been used for validation and is now inferior or redundant to the chosen entry for the same finding - validated - FReD but not COS: applies to replication studies that do not contain statistical test (e.g., replications in the qualitative humanities) | E3: for data matching. DO NOT EDIT - keep blank for new rows | F3: Sample id. DO NOT CHANGE. If you add samples, copy and add _b, _c etc | G3: *Add* your name when you edit the row | H3: (dd/mm/yyyy) | I3: (dd/mm/yyyy) | J3: general data entry notes, e.g., re access issues or study selection | K3: only used by core team | L3: Copy APA style from Google Scholar (or similar), without DOI | M3: without URL prefix, so starting with 10.xx | N3: Number of study in paper, e.g., 1 or 2A | O3: file-name for O PDF - only edit if DOI is missing | Q3: Copy APA style from Google Scholar (or similar), without DOI | R3: without URL prefix, so starting with 10.xx | S3: Link to R results - only when DOI missing or for aggregate report | T3: Number of study in paper, e.g., 1 or 2A | U3: file-name for R PDF - only edit if DOI is missing | V3: How does R identify as replication in title or abstract? Usually "replication" but report different wording if used | X3: Reason for study exclusion (usually only if R is not a replication) | Y3: Which broad field does the finding come from - e.g., Social Psychology or Labor Economics | Z3: x | AA3: tags to increase findability - e.g. keywords from abstract | AB3: Description of the effect under investigation (e.g., x is associated with y, x leads to y), possibly a part of the original publication's title (abstract claim) | AC3: The authors’ key statistical result and its interpretation | AD3: Page number(s) for claim_text_o | AE3: O's sample size [used for the critical test, i.e., after exclusion criteria have been applied], must contain only one value and must not contain text | AF3: original effect size value, must contain only one value and must not contain text | AG3: original effect size type (e.g., d, r, r², etasq) | AH3: Reproducible origin/calculation method for es_value_o ("p. xx" when reported, link when available online - e.g., OSF, otherwise calculation process) | AI3: The reported p-value associated with the original finding, must contain only one value and must not contain text | AJ3: How is p-val reported? "=" (e) / "<" (l) / ">" (g) or combined (le, ge)? for example "p <= .05" should be coded as "le" | AK3: How many tails associated with the p-value, taking on values of one, two, or unknown one: 1 two: 2 unknown / not specified: NA missing: not coded | AL3: Is pval based on a test that accounts for dependence between observations (e.g., multilevel, repeated measures) | AM3: Link to preregistration of O (only search for "regist") | AN3: R's sample size [used for the critical test, i.e., after exclusion criteria have been applied], must contain only one value and must not contain text | AO3: replication effect size value, must contain only one value and must not contain text | AP3: replication effect size type | AQ3: Reproducible origin/calculation method for es_value_r ("p. xx" when reported, otherwise calculation process) | AR3: The reported p-value associated with the replication finding, must contain only one value and must not contain text | AS3: How is p-val reported? "=" (e) / "<" (l) / ">" (g) or combined (le, ge)? for example "p <= .05" should be coded as "le" | AT3: How many tails associated with the p-value, taking on values of one, two, or unknown one: 1 two: 2 unknown: NA missing: not coded | AU3: Is pval based on a test that accounts for dependence between observations (e.g., multilevel, repeated measures) | AV3: Link to preregistration of R (only search for "regist") | AW3: NA: unknown 1: internal: all central features are highly similar AND conducted by at least one of the original researchers 2: close/direct: central features are highly similar AND none of the original authors is involved 3: conceptual/constructive/extension: central features are different, theoretically relevant aspects are the same; authorship overlap is irrelevant | AY3: name of the person who validated the entry
A4: validated - discarded | B4: double | C4: Maureen | E4: 2zgf9_1 | F4: 2zgf9 | G4: Kateri McRae, Daniel Lumian, Mallory C. Kidwell, Johanna Cohoon, Lilian Hummer | H4: 1.1.2023 | I4: 45641 | J4: coding tasks 2zgf9_1, bth36_1, and 7vgkq_1 are similar; the partial-eta squared reported in the replication paper of 0.226 is different from the value in OSF registries of 0.313, hence requires validation; Psychological science has not been listed as one of the disciplines, hence categorizing them as political science | L4: Cunningham, W. A., Van Bavel, J. J., & Johnsen, I. R. (2008). Affective flexibility: evaluative processing goals shape amygdala activity. Psychological Science, 19(2), 152-160. | M4: 10.1111/j.1467-9280.2008.02061.x | N4: 1 | O4: 10.1111--j.1467-9280.2008.02061.x.pdf | P4: {=HYPERLINK(INDEX('File Links'!B:B, MATCH(O4, 'File Links'!C:C, 0)))} -> https://drive.google.com/file/d/140WKvPe6h8fNM79ffoPo5RX6uP0flGT4/view?usp=drivesdk | Q4: McRae, K., & Lumian, D. S. (2023, September 28). Replication of WA Cunningham, JJ Van Bavel, IR Johnsen (2008, PS 19 (2)). https://doi.org/10.17605/OSF.IO/2ZGF9 | R4: 10.17605/OSF.IO/2ZGF9 | T4: 1 | U4: 10.17605--osf.io--2zgf9.pdf | V4: replication attempt | W4: {=HYPERLINK(INDEX('File Links'!B:B, MATCH(U4, 'File Links'!C:C, 0)))} -> https://drive.google.com/file/d/15dLELTosbF1NWFYI0UOSPLIC70dnGG5S/view?usp=drivesdk | Y4: Political Science | AA4: affective flexibility, amygdala, valence, stimulus | AB4: interaction between scanning condition (positive or negative) and stimulus valence | AC4: "results were consistent with the idea of affective flexibility. There was a significant interaction between scanning condition (positive or negative) and stimulus valence (postscan ratings of positivity or negativity), F(1, 11) = 9.67, p < .01, prep = .95" | AD4: p. 7 | AE4: 12 | AF4: 9.67 | AG4: F test statistic | AH4: p. 7 | AI4: 0.01 | AJ4: l (<) | AK4: 2 (two) | AL4: no | AN4: 39 | AO4: 0.226 | AP4: etasq | AQ4: p. 6 | AR4: 0.02 | AS4: l (<) | AT4: 2 (two) | AU4: yes | AV4: https://doi.org/10.17605/OSF.IO/2ZGF9 | AW4: 2 - close | AY4: LR
A5: validated - discarded | B5: double | C5: Jyoti | E5: 2zgf9_1 | F5: 2zgf9 | G5: Kateri McRae, Daniel Lumian, Mallory C. Kidwell, Johanna Cohoon, Lilian Hummer, Jyoti Bhogal | H5: 45108 | I5: 45644 | L5: Cunningham, W. A., Van Bavel, J. J., & Johnsen, I. R. (2008). Affective flexibility: evaluative processing goals shape amygdala activity. Psychological Science, 19(2), 152-160. | M5: 10.1111/j.1467-9280.2008.02061.x | N5: 1 | O5: 10.1111--j.1467-9280.2008.02061.x.pdf | P5: {=HYPERLINK(INDEX('File Links'!B:B, MATCH(O5, 'File Links'!C:C, 0)))} -> https://drive.google.com/file/d/140WKvPe6h8fNM79ffoPo5RX6uP0flGT4/view?usp=drivesdk | Q5: McRae, K., & Lumian, D. S. (2023, September 28). Replication of WA Cunningham, JJ Van Bavel, IR Johnsen (2008, PS 19 (2)). https://doi.org/10.17605/OSF.IO/2ZGF9 | R5: 10.17605/OSF.IO/2ZGF9 | U5: 10.17605--osf.io--2zgf9.pdf | W5: {=HYPERLINK(INDEX('File Links'!B:B, MATCH(U5, 'File Links'!C:C, 0)))} -> https://drive.google.com/file/d/15dLELTosbF1NWFYI0UOSPLIC70dnGG5S/view?usp=drivesdk | X5: no replication report available but only a post completion registration | Y5: Cognitive Psychology | AA5: affective flexibility, amygdala, positive names, negative names | AE5: 12 | AO5: 0.313 | AR5: unavailable | AW5: 3 - conceptual | AY5: LR
A6: validated - chosen | B6: double | C6: Nikita | E6: 39xuw_1 | F6: 39xuw | G6: Nikita | H6: 45638 | I6: 45680 | J6: 1. Values for the REPLICATION statistical inferences were taken from Files uploaded to OSF by a link: https://osf.io/39xuw/files/osfstorage. I merged them in the corresponding PDF | K6: corrected N from 150 to 137 | L6: Schaffer, J., & Knobe, J. (2012). Contrastive knowledge surveyed. Noûs, 46(4), 675-708. | M6: 10.1111/j.1468-0068.2010.00795.x | N6: 1 | O6: 10.1111--j.1468-0068.2010.00795.x.pdf | P6: {=HYPERLINK(INDEX('File Links'!B:B, MATCH(O6, 'File Links'!C:C, 0)))} -> https://drive.google.com/file/d/1O4mjB0-ZSujMTJYtaAoIsXTPuhxgEF-0/view?usp=drivesdk | Q6: Wilkenfeld, D. A., & Hernández-Conde, J. V. (2017, September 12). Schaffer and Knobe Replication. https://doi.org/10.17605/OSF.IO/39XUW | R6: 10.17605/OSF.IO/39XUW | T6: 1 | U6: 10.17605--osf.io--39xuw.pdf | V6: Replication | W6: {=HYPERLINK(INDEX('File Links'!B:B, MATCH(U6, 'File Links'!C:C, 0)))} -> #N/A | Y6: Experimental Philosophy | Z6: Contrast sensitivity of knowledge ascription (contrastivism) | AA6: Contrastivism, knowledge, knowledge ascription, "rather than" clause, contrast, context | AB6: The two conditions of the experiment involve ascribing knowledge of the very same proposition ("rather than" clause) and they differ only in that they pick out two different contrasts to that proposition: subject or object. | AC6: "Participants in the thief contrast condition tended to agree with the knowledge ascription they received (mean rating: 4.6), while participants in the jewel contrast condition tended to disagree with the knowledge ascription they received (mean rating: 3.1)." | AD6: 16 | AE6: 100 | AF6: t(98) = 3.4 | AG6: test statistic | AH6: p.31 | AI6: 0.001 | AJ6: e (=) | AK6: 2 (two) | AL6: no | AM6: NA | AN6: 137 | AO6: 0.584 | AP6: d | AQ6: p.2 of https://osf.io/k2cna | AR6: 0.001 | AS6: l (<) | AT6: 2 (two) | AU6: no | AV6: https://osf.io/39xuw | AW6: 2 - close | AY6: LR
A7: validated - discarded | B7: double | C7: Husnain | E7: 39xuw_1 | F7: 39xuw | G7: Husnain | H7: 45641 | I7: 45680 | J7: 1. The tags are not given explicitly so I have inferred from the introduction of orignal paper. 2. The effect size is not reprted in the orignal study while replication has reported it's own and the effect size of replication study the infered effect size is cohen's d 0.687. 3. The replication paper has reported cohen's d for the replicated study without the p value, however, it presented p valur for test stastic without the value of t. | L7: Schaffer, J., & Knobe, J. (2012). Contrastive knowledge surveyed. Noûs, 46(4), 675-708. | M7: 10.1111/j.1468-0068.2010.00795.x | O7: 10.1111--j.1468-0068.2010.00795.x.pdf | P7: {=HYPERLINK(INDEX('File Links'!B:B, MATCH(O7, 'File Links'!C:C, 0)))} -> https://drive.google.com/file/d/1O4mjB0-ZSujMTJYtaAoIsXTPuhxgEF-0/view?usp=drivesdk | Q7: Wilkenfeld, D. A., & Hernández-Conde, J. V. (2017, September 12). Schaffer and Knobe Replication. https://doi.org/10.17605/OSF.IO/39XUW | R7: 10.17605/OSF.IO/39XUW | U7: 10.17605--osf.io--39xuw.pdf | V7: Replication | W7: {=HYPERLINK(INDEX('File Links'!B:B, MATCH(U7, 'File Links'!C:C, 0)))} -> #N/A | Y7: Experimental Philosophy | Z7: contrastive knowledge | AA7: contrastive model, invariantist models, contextualist models, knowlege acriptions, conversational context | AB7: Thief contrast codition tend to agree more compared to jewel contrast condition with knowledge ascription | AC7: "N = 100 people spending time in the Canberra Centre Mall in Canberra, Australia, t (98) = 3.4, p = .001." | AD7: p. 16 | AE7: 100 | AF7: 3.4 | AG7: test statistic | AH7: p. 16, 31 | AI7: 0.001 | AJ7: e (=) | AK7: NA (not reported) | AL7: no | AN7: 137 | AO7: 0.584 | AP7: Cohen's d | AQ7: p. 1,2 | AV7: https://osf.io/39xuw | AW7: 2 - close | AY7: LR
A8: validated - discarded | B8: double | C8: Maureen | E8: 7vgkq_1 | F8: 7vgkq | G8: Kateri McRae, Mallory C. Kidwell, Johanna Cohoon, Daniel Lumian, Lilian Hummer, TESS-Experiments | H8: 1.1.2023 | I8: 45641 | J8: coding tasks 2zgf9_1, bth36_1, and 7vgkq_1 are similar; the partial-eta squared reported in the replication paper of 0.226 is different from the value in OSF registries of 0.313, hence requires validation; Psychological science has not been listed as one of the disciplines, hence categorizing them as political science | L8: Cunningham, W. A., Van Bavel, J. J., & Johnsen, I. R. (2008). Affective flexibility: evaluative processing goals shape amygdala activity. Psychological Science, 19(2), 152-160. | M8: 10.1111/j.1467-9280.2008.02061.x | N8: 1 | O8: 10.1111--j.1467-9280.2008.02061.x.pdf | P8: {=HYPERLINK(INDEX('File Links'!B:B, MATCH(O8, 'File Links'!C:C, 0)))} -> https://drive.google.com/file/d/140WKvPe6h8fNM79ffoPo5RX6uP0flGT4/view?usp=drivesdk | Q8: McRae, K., Lumian, D. S., & T. (2023, September 28). Materials. https://doi.org/10.17605/OSF.IO/7VGKQ | R8: 10.17605/OSF.IO/7VGKQ | U8: 10.17605--osf.io--7vgkq.pdf | V8: replication attempt | W8: {=HYPERLINK(INDEX('File Links'!B:B, MATCH(U8, 'File Links'!C:C, 0)))} -> #N/A | Y8: Political Science | AA8: affective flexibility, amygdala, valence, stimulus | AD8: p. 7 | AE8: 12 | AF8: 9.67 | AG8: F test statistic | AH8: p. 7 | AI8: 0.01 | AJ8: l (<) | AK8: 2 (two) | AL8: no | AN8: 39 | AO8: 0.226 | AP8: etasq | AQ8: p. 6 | AR8: 0.02 | AS8: l (<) | AT8: 2 (two) | AU8: yes | AV8: https://doi.org/10.17605/OSF.IO/7VGKQ | AW8: 2 - close | AY8: LR
A9: validated - discarded | B9: double | C9: Jyoti | E9: 7vgkq_1 | F9: 7vgkq | G9: Kateri McRae, Mallory C. Kidwell, Johanna Cohoon, Daniel Lumian, Lilian Hummer, TESS-Experiments, Jyoti Bhogal | H9: 45170 | I9: 45644 | L9: Cunningham, W. A., Van Bavel, J. J., & Johnsen, I. R. (2008). Affective flexibility: evaluative processing goals shape amygdala activity. Psychological Science, 19(2), 152-160. | M9: 10.1111/j.1467-9280.2008.02061.x | N9: 1 | O9: 10.1111--j.1467-9280.2008.02061.x.pdf | P9: {=HYPERLINK(INDEX('File Links'!B:B, MATCH(O9, 'File Links'!C:C, 0)))} -> https://drive.google.com/file/d/140WKvPe6h8fNM79ffoPo5RX6uP0flGT4/view?usp=drivesdk | Q9: McRae, K., Lumian, D. S., & T. (2023, September 28). Materials. https://doi.org/10.17605/OSF.IO/7VGKQ | R9: 10.17605/OSF.IO/7VGKQ | U9: 10.17605--osf.io--7vgkq.pdf | W9: {=HYPERLINK(INDEX('File Links'!B:B, MATCH(U9, 'File Links'!C:C, 0)))} -> #N/A | X9: no replication report available but only a post completion registration | Y9: Cognitive Psychology | AA9: affective flexibility, amygdala, positive names, negative names | AO9: 0.313 | AR9: unavailable | AY9: LR
A10: validated - discarded | B10: double | C10: Nikolay | E10: acykd_1 | F10: acykd | G10: Nikolay Petrov | H10: 45639 | J10: original sample size is 42, but 1 was excluded afterwards (p. 137) | K10: - Please type "NA" if you could not find "regis" in the manuscript. - Good catch with the N = 41! - This is the preregistration: https://osf.io/8urxv It is linked at the top of the entry | L10: Mussweiler, T., & Englich, B. (2005). Subliminal anchoring: Judgmental consequences and underlying mechanisms. Organizational Behavior and Human Decision Processes, 98(2), 133-143. | M10: 10.1016/j.obhdp.2004.12.002 | N10: 2 | O10: =hyperlink(vlookup(lower(M10),'File Links'!A:B, 2, FALSE), SUBSTITUTE(lower(M10), "/", "--") & ".pdf") -> 10.1016--j.obhdp.2004.12.002.pdf | P10: {=HYPERLINK(INDEX('File Links'!B:B, MATCH(O10, 'File Links'!C:C, 0)))} -> https://drive.google.com/file/d/1CZ8RmInPe2eqHwf-p8tl0IQxpn8_H_C5/view?usp=drivesdk | Q10: Röseler, L., Schütz, A., Burlakovas, E., Dück, M., Fels, S., Janiczek, S., … Seida, C. (2022, September 15). Replication Mussweiler & Englich, 2005, Study 2. https://doi.org/10.17605/OSF.IO/ACYKD | R10: 10.17605/OSF.IO/ACYKD | U10: 10.17605--osf.io--acykd.pdf | V10: replication | W10: {=HYPERLINK(INDEX('File Links'!B:B, MATCH(U10, 'File Links'!C:C, 0)))} -> #N/A | Y10: Judgment and Decision Making | Z10: subliminal anchoring | AA10: anchoring, subliminal priming, judgment bias, decision-making | AB10: estimates for numeric judgments are assimilated toward anchor values, even when these anchors are presented subliminally and outside of conscious awareness | AC10: Participants who were presented with the high anchor value estimated the car price to be higher (M = 21,219 Euro) than those presented with the low anchor value (M = 17,150 Euro), t(39) = 2.02, p < .05, r = .31. | AD10: 137 | AE10: 41 | AF10: 0.31 | AG10: r | AH10: p. 137 | AI10: 0.05 | AJ10: l (<) | AK10: NA (not reported) | AL10: no | AN10: 165 | AO10: -0.148 | AP10: d | AQ10: p. 3 | AR10: 0.83 | AS10: e (=) | AT10: 1 (one) | AU10: no | AV10: https://pdf.sciencedirectassets.com/272387/1-s2.0-S0022103120X00060/1-s2.0-S0022103120304066/main.pdf?X-Amz-Security-Token=IQoJb3JpZ2luX2VjEBgaCXVzLWVhc3QtMSJGMEQCICnHJqcNsP62IhJ5t%2BlQbccPwseA76qFfK6Rgkom8dtRAiB1LS%2BiM%2B0b%2BvwiyOom715iyNnHeXVQbXmSm95pdglacyq8BQjR%2F%2F%2F%2F%2F%2F%2F%2F%2F%2F8BEAUaDDA1OTAwMzU0Njg2NSIMmoze3y0Q1yERk%2B0lKpAF0gYTSXrqATr%2FlouJQrzfzrF%2B%2BHvghuPve%2FIY6N1xxaQBobJn18bDe0NKhRM4T2mvBEFjCOaVSqmUoM3%2F%2BmGL%2BTAQq6mB%2F5aQpDiqXVVnBGSq5%2F03UsrB78W9ZYcX3HuqmMRCwLpHPAIgIHd9zQtRRFGwk6RR%2ByNdrZ7EqjeWgcIKuyAr9%2Bj0JJ74pqGzqA1bFSaiBMqqZjviAxsq%2FjIO4yKprM2jCQw%2B%2FbZMITGLBdecPGFvQADAleUhJZgsYDQbMSkktZJ6E%2FJW5MtMzDJ3LrlhsdSqiHd28N4%2FJtYL8gNCs%2F9wK3a1s%2BQvM838pcLinkI8unVh1Gcvfxjbq6fYI6x4hCc7UZUEXs%2BEd%2Bo1x9GFvp3tcM%2BwJYlAa%2BEE%2FZcco8Dj58jnqzyOal0dDMeeWOjHL3y8xqwOE69icvonadJhHFVwONEoA1aox7vcITDF0spX53bm8Off4OeJ4bHC6QFHjIgBmUnwwVhqwcTI1CofN%2BPxww0zY3oNg4NrIO%2B5IVffRucPE9pztEeVHOdsmVPWyRlEFrjQ3aVJiYpL6TVfW3VfFLrAFifjveRxLAGB28CYsVXmTUz0Qxq6JRu7SlmaRNP2YnG7ipXXbiuZbwrorkm%2BxDc3uzBAI3Z82HTq1%2FmzxXw3SDN8%2FgQpgwWMXmWr%2F%2BckEKS7a7j2988ql%2B%2Fy%2BqfrHVJ5rVoDXKUgDUP6rR3X1ejf1UZwyc8ja5HXFbPfOefIT%2FsnbjIx3Ff255FID0Z6RGepP7orcagCAcWl7CBXLkbWM%2BaP6Oi1ITpYGOPrwvSeRMyKPH2NmAiiWZE5l0m%2FTJGJ0tND%2FrcK%2BOlvjkyuEOx33q4BZeSRwvKBTPBeeTtjgd9K%2BGRMok%2Fe5xEw28zvugY6sgH0sfyibldLqTratcbSkw7B9kA7YzvSU7Iyhc8zjvj18adk0B6r39A2zAda5VndB8QXUitJ8361WDPVPzGMTek%2Fl5bziH%2FtLRb2uo30VQ5T74JJWTp8l6Rs7L5pQAvE%2FQTclPBuc%2BZrz7CkEfVLz%2FJt0xicBVpzawZjnQzXuFBfBBbMr%2FWdBHYYpRqC6jMqh3zJIYsu9ZeQkzwiXFbF14t%2BITCuLmhK4klb9H3%2BQ4iKcUaK&X-Amz-Algorithm=AWS4-HMAC-SHA256&X-Amz-Date=20241213T084150Z&X-Amz-SignedHeaders=host&X-Amz-Expires=300&X-Amz-Credential=ASIAQ3PHCVTYUWRHKPES%2F20241213%2Fus-east-1%2Fs3%2Faws4_request&X-Amz-Signature=33924dc8199c3da89949ad504da4000be209df455000e1a7e4fee4140f60b1b1&hash=6979ab83d6e022fd52840830bb00b033291cf8235f9e721ac49f027cf55e995c&host=68042c943591013ac2b2430a89b270f6af2c76d8dfd086a07176afe7c76c2c61&pii=S0022103120304066&tid=spdf-0273d28f-03b4-4283-8694-d21fc2577d91&sid=18412b78662c794bb67b6200a74126f2bac9gxrqb&type=client&tsoh=d3d3LnNjaWVuY2VkaXJlY3QuY29t&ua=010859005455035b5a&rr=8f14a84b18840c73&cc=bg#link_ir0025 | AW10: 2 - close | AX10: - Please type "NA" if you could not find "regis" in the manuscript. - Good catch with the N = 41! - This is the preregistration: https://osf.io/8urxv It is linked at the top of the entry | AY10: LR
A11: validated - chosen | B11: double | C11: Hakile | E11: acykd_1 | F11: acykd | G11: Hakile Resulbegoviq | H11: 45641 | I11: 45663 | J11: informative failure to replicate | K11: updated reference_r to report instead of the OSF page | L11: Mussweiler, T., & Englich, B. (2005). Subliminal anchoring: Judgmental consequences and underlying mechanisms. Organizational Behavior and Human Decision Processes, 98(2), 133-143. | M11: 10.1016/j.obhdp.2004.12.002 | N11: 2 | O11: =hyperlink(vlookup(lower(M11),'File Links'!A:B, 2, FALSE), SUBSTITUTE(lower(M11), "/", "--") & ".pdf") -> 10.1016--j.obhdp.2004.12.002.pdf | P11: {=HYPERLINK(INDEX('File Links'!B:B, MATCH(O11, 'File Links'!C:C, 0)))} -> https://drive.google.com/file/d/1CZ8RmInPe2eqHwf-p8tl0IQxpn8_H_C5/view?usp=drivesdk | Q11: Röseler, L., Schütz, A., Blank, P. A., Dück, M., Fels, S., Kupfer, J., ... & Seida, C. (2021). Evidence against subliminal anchoring: Two close, highly powered, preregistered, and failed replication attempts. Journal of Experimental Social Psychology, 92, 104066. https://doi.org/10.1016/j.jesp.2020.104066 | R11: 10.1016/j.jesp.2020.104066 | T11: 1 | U11: 10.17605--osf.io--acykd.pdf | V11: Replication | W11: {=HYPERLINK(INDEX('File Links'!B:B, MATCH(U11, 'File Links'!C:C, 0)))} -> #N/A | Y11: Social Psychology | Z11: Subliminal anchoring | AA11: Anchoring; Heuristics; Comparison; Selective accessibility; Assimilation | AB11: Subliminally presented numerical anchors influence judgment, causing estimates to shift toward the anchor values without participants being consciously aware of the anchors. | AC11: Participants who were presented with the high anchor value estimated the car price to be higher (M = 21,219 Euro) than those presented with the low anchor value (M = 17,150 Euro), t(39) = 2.02, p < .05, r = .31. | AD11: 137 | AE11: 41 | AF11: 0.31 | AG11: r | AH11: p. 137 | AI11: 0.05 | AJ11: l (<) | AK11: NA (not reported) | AL11: no | AM11: NA | AN11: 165 | AO11: -0.148 | AP11: d | AQ11: p. 3 | AR11: 0.83 | AS11: e (=) | AT11: 1 (one) | AU11: no | AV11: https://osf.io/8urxv | AW11: 2 - close | AX11: Feedback for Hakile: - The degreees of freedom for the t test are 39, indicating that N = 41 - the number of tails was actually not reported (it does not say anywhere whether it is one-tailed or two-tailed but was coded as 2) - I could not find the d = 0.71 on p. 137 or anywhere in the manuscript. - Please type "NA" if you could not find "regis" in the manuscript. - Please rather use text for the claim that includes statistical elements, such as the effect on p. 137 under "results and discussion" - This is the preregistration: https://osf.io/8urxv It is linked at the top of the entry. You linked the "post completion" registration. | AY11: LR
A12: validated - chosen | B12: double | C12: Sarah | E12: additional_studies1_1 | F12: additional_studies1_a | G12: SAJ | H12: 45427 | I12: 45624 | L12: Rellensmann, J., & Schukajlow, S. (2017). Does students’ interest in a mathematical problem depend on the problem’s connection to reality? An analysis of students’ interest and pre-service teachers’ judgments of students’ interest in problems with and without a connection to reality. ZDM, 49, 367-378. https://doi.org/10.1007/s11858-016-0819-3 | M12: 10.1007/s11858-016-0819-3 | N12: 1 | O12: =hyperlink(vlookup(lower(M12),'File Links'!A:B, 2, FALSE), SUBSTITUTE(lower(M12), "/", "--") & ".pdf") -> 10.1007--s11858-016-0819-3.pdf | P12: {=HYPERLINK(INDEX('File Links'!B:B, MATCH(O12, 'File Links'!C:C, 0)))} -> https://drive.google.com/file/d/1A3A0XWewbvFp536VbiCjIAYxdIJwVP-9/view?usp=drivesdk | Q12: García-Cerdá, C., Segura, C., & Ferrando, I. (2024). Influence of the Type of Mathematical Problems on Students’ and Pre-service Teachers’ Interest and Performance. A Replication and Elaboration Study. Implementation and Replication Studies in Mathematics Education, 1(aop), 1-35. https://doi.org/10.1163/26670127-bja10017 | R12: 10.1163/26670127-bja10017 | T12: 1 | U12: =hyperlink(vlookup(lower(R12),'File Links'!E:F, 2, FALSE), SUBSTITUTE(lower(R12), "/", "--") & ".pdf") -> 10.1163--26670127-bja10017.pdf | V12: Title - "A replication and elaboration study" Abstract - "... the process of conceptual replication of Rellensmann and Schukajlow’s (2017) research..." | W12: {=HYPERLINK(INDEX('File Links'!B:B, MATCH(U12, 'File Links'!C:C, 0)))} -> #N/A | Y12: Education | Z12: interest in mathematics | AA12: mathematics, interest, students, pre-service teachers, diagnostic competence, real-world problems, performance, problem-solving | AB12: Influence of the Type of Mathematical Problems on Students’ Interest | AC12: A t-test for dependent samples indicated that the difference in students’ interest in the two problem types was statistically significant [t(99) = −2.96, p < 0.01]. | AD12: 7 | AE12: 100 | AF12: 0.3 | AG12: d | AH12: p. 7 | AI12: p < 0.01 | AJ12: l (<) | AK12: NA (not reported) | AL12: yes | AM12: NA | AN12: 80 | AO12: 𝜒2(2) = 9.99 | AP12: test statistic | AQ12: preprint p. 22 Kendells W = X2/N(K-1), X2 = 9.99, N = 80, K = 3 W = 9.99/ (80*(3-1)), W = 9.99/ (160), W ~ 0.06 | AR12: 0.01 | AS12: l (<) | AT12: NA (not reported) | AU12: no | AV12: NA | AW12: 2 - close | AY12: LR
A13: validated - discarded | B13: double | C13: Alexsandr | E13: additional_studies1_1 | F13: additional_studies1_a | G13: Aleksandr Pravednikov | H13: 45427 | I13: 45625 | J13: Claim text_r We observe that, in terms of means, there are no great differences in interest according to the type of problem. For students intramathematical problems were the most interesting (Mi = 2.77, SDi = 1.25), followed by word problems (Mw = 2.75, SDw = 1.18), and finally by modelling problems (Mm = 2.66, SDm = 1.26). - Table 1. To analyse whether the differences are significant, a hypothesis test was performed. Given that the means of interest did not follow, according to the results of the Shapiro-Wilk test, a normal distribution in any of the three types of problems, we applied Friedman’s non-parametric test. Thus, we obtained that there were differences between at least two types of problems (𝜒𝜒2(2)=9.99, p < 0.01). A post hoc analysis, using the Nemenyi test, ensured that there were significant differences in task-specific interest between word and modelling problems (p < 0.05), but not between the other combinations. [...] Page 21-22 | L13: Rellensmann, J., & Schukajlow, S. (2017). Does students’ interest in a mathematical problem depend on the problem’s connection to reality? An analysis of students’ interest and pre-service teachers’ judgments of students’ interest in problems with and without a connection to reality. ZDM, 49, 367-378. https://doi.org/10.1007/s11858-016-0819-3 | M13: 10.1007/s11858-016-0819-3 | O13: =hyperlink(vlookup(lower(M13),'File Links'!A:B, 2, FALSE), SUBSTITUTE(lower(M13), "/", "--") & ".pdf") -> 10.1007--s11858-016-0819-3.pdf | P13: {=HYPERLINK(INDEX('File Links'!B:B, MATCH(O13, 'File Links'!C:C, 0)))} -> https://drive.google.com/file/d/1A3A0XWewbvFp536VbiCjIAYxdIJwVP-9/view?usp=drivesdk | Q13: García-Cerdá, C., Segura, C., & Ferrando, I. (2024). Influence of the Type of Mathematical Problems on Students’ and Pre-service Teachers’ Interest and Performance. A Replication and Elaboration Study. Implementation and Replication Studies in Mathematics Education, 1(aop), 1-35. https://doi.org/10.1163/26670127-bja10017 | R13: 10.1163/26670127-bja10017 | U13: =hyperlink(vlookup(lower(R13),'File Links'!E:F, 2, FALSE), SUBSTITUTE(lower(R13), "/", "--") & ".pdf") -> 10.1163--26670127-bja10017.pdf | W13: {=HYPERLINK(INDEX('File Links'!B:B, MATCH(U13, 'File Links'!C:C, 0)))} -> #N/A | Y13: Educational Sciences | AA13: Students | AB13: Influence of the Type of Mathematical Problems on Students’ and Pre-service Teachers’ Interest and Performance | AC13: Students reported a mean level of interest of Madj = 2.71 (SDadj = 0.90) in solving problems with a connection to reality and Madj = 2.91 (SDadj = 1.00) in solving problems without a connection to reality when the impact of task difficulty was controlled for (Table 2). Means and standard errors for students’ interest are graphically displayed in Fig. 4. A t-test for dependent samples indicated that the difference in students’ interest in the two problem types was statistically significant [t(99) = −2.96, p < 0.01]. Cohen’s d = 0.30 indicated a small effect. This means that, contrary to our expectations, students reported more interest in solving problems without a connection to reality thann in problems with a connection to reality. | AD13: 7(373) | AE13: 100 | AF13: 0.3 | AG13: d | AI13: < 0.01 | AJ13: l (<) | AK13: NA (not reported) | AN13: 80 | AR13: p < 0.05 | AS13: l (<) | AT13: NA (not reported) | AW13: 2 - close | AY13: LR
A14: validated - chosen | B14: double | C14: Sarah | E14: additional_studies1_1 | F14: additional_studies1_b | G14: SAJ | H14: 45427 | I14: 45624 | J14: this effect was not explored in the original paper | L14: Rellensmann, J., & Schukajlow, S. (2017). Does students’ interest in a mathematical problem depend on the problem’s connection to reality? An analysis of students’ interest and pre-service teachers’ judgments of students’ interest in problems with and without a connection to reality. ZDM, 49, 367-378. https://doi.org/10.1007/s11858-016-0819-3 | M14: 10.1007/s11858-016-0819-3 | N14: 1 | O14: =hyperlink(vlookup(lower(M14),'File Links'!A:B, 2, FALSE), SUBSTITUTE(lower(M14), "/", "--") & ".pdf") -> 10.1007--s11858-016-0819-3.pdf | P14: {=HYPERLINK(INDEX('File Links'!B:B, MATCH(O14, 'File Links'!C:C, 0)))} -> https://drive.google.com/file/d/1A3A0XWewbvFp536VbiCjIAYxdIJwVP-9/view?usp=drivesdk | Q14: García-Cerdá, C., Segura, C., & Ferrando, I. (2024). Influence of the Type of Mathematical Problems on Students’ and Pre-service Teachers’ Interest and Performance. A Replication and Elaboration Study. Implementation and Replication Studies in Mathematics Education, 1(aop), 1-35. https://doi.org/10.1163/26670127-bja10017 | R14: 10.1163/26670127-bja10017 | T14: 1 | U14: =hyperlink(vlookup(lower(R14),'File Links'!E:F, 2, FALSE), SUBSTITUTE(lower(R14), "/", "--") & ".pdf") -> 10.1163--26670127-bja10017.pdf | V14: Title - "A replication and elaboration study" Abstract - "... the process of conceptual replication of Rellensmann and Schukajlow’s (2017) research..." | W14: {=HYPERLINK(INDEX('File Links'!B:B, MATCH(U14, 'File Links'!C:C, 0)))} -> #N/A | Y14: Education | Z14: interest in mathematics | AA14: mathematics, interest, students, pre-service teachers, diagnostic competence, real-world problems, performance, problem-solving | AB14: Influence of the Type of Mathematical Problems on Pre-service Teachers’ Interest | AC14: A t-test for dependent samples showed a significant difference in pre-service teachers’ judgments of students’ interest in solving the two types of problems [t(162) = 14.33, p < 0.01]. Cohen’s d = 1.12 | AD14: 7 | AE14: 163 | AF14: 1.12 | AG14: d | AH14: p. 7 | AI14: < 0.01 | AJ14: l (<) | AK14: NA (not reported) | AL14: yes | AM14: NA | AN14: 80 | AO14: 𝜒2(2) = 16.54 | AP14: test statistic | AQ14: Kendells W = X2/N(K-1), X2 = 16.54, N = 80, K = 3 W = 16.54/ (80*(3-1)), W = 16.54/ (160), W ~ 0.1 | AR14: 0.01 | AS14: l (<) | AT14: NA (not reported) | AU14: no | AV14: NA | AW14: 2 - close | AY14: LR
A15: validated - discarded | B15: double | C15: Alexsandr | E15: additional_studies1_1 | F15: additional_studies1_b | G15: Aleksandr Pravednikov | H15: 45427 | I15: 45625 | J15: Claim text_r Table 2 shows the average situational interest of 80 pre-service teachers according to the connection to the reality of the problems. We observe that, for pre-service teachers, word problems were the most interesting (Mw = 3.28, SDw = 1.22), followed by modelling problems (Mm = 3.11, SDm = 1.25) and, finally, intramathematical problems (Mi = 2.92, SDi = 1.24). Again, we conducted a hypothesis test to analyse whether there were significant differences in interest according to the connection with the reality of the problems. The means of interest did not follow a normal distribution either, so we obtained that there are significant differences between at least two types of problems (𝜒𝜒2(2)=16.54, p < 0.01) by applying Friedman’s test. Nemenyi’s test ensured that there were significant differences in task-specific interest between word and modelling problems (p < 0.05), and between intramathematical and word problems (p < 0.01). There were no significant differences between intramathematical and modelling problems (p = 0.46), indicating that word problems were significantly more interesting for pre-service teachers. [...] Page 22-23 | L15: Rellensmann, J., & Schukajlow, S. (2017). Does students’ interest in a mathematical problem depend on the problem’s connection to reality? An analysis of students’ interest and pre-service teachers’ judgments of students’ interest in problems with and without a connection to reality. ZDM, 49, 367-378. https://doi.org/10.1007/s11858-016-0819-3 | M15: 10.1007/s11858-016-0819-3 | O15: =hyperlink(vlookup(lower(M15),'File Links'!A:B, 2, FALSE), SUBSTITUTE(lower(M15), "/", "--") & ".pdf") -> 10.1007--s11858-016-0819-3.pdf | P15: {=HYPERLINK(INDEX('File Links'!B:B, MATCH(O15, 'File Links'!C:C, 0)))} -> https://drive.google.com/file/d/1A3A0XWewbvFp536VbiCjIAYxdIJwVP-9/view?usp=drivesdk | Q15: García-Cerdá, C., Segura, C., & Ferrando, I. (2024). Influence of the Type of Mathematical Problems on Students’ and Pre-service Teachers’ Interest and Performance. A Replication and Elaboration Study. Implementation and Replication Studies in Mathematics Education, 1(aop), 1-35. https://doi.org/10.1163/26670127-bja10017 | R15: 10.1163/26670127-bja10017 | U15: =hyperlink(vlookup(lower(R15),'File Links'!E:F, 2, FALSE), SUBSTITUTE(lower(R15), "/", "--") & ".pdf") -> 10.1163--26670127-bja10017.pdf | W15: {=HYPERLINK(INDEX('File Links'!B:B, MATCH(U15, 'File Links'!C:C, 0)))} -> #N/A | Y15: Educational Sciences | AA15: Pre-service teachers | AB15: Influence of the Type of Mathematical Problems on Students’ and Pre-service Teachers’ Interest and Performance | AC15: Pre-service teachers predicted a mean of Madj = 3.18 (SDadj = 0.48) for students’ interest in problems with a connection to reality and Madj = 2.47 (SDadj = 0.60) for their interest in problems without a connection to reality (Table 2). Means and standard errors for pre-service teachers’ judgments are also graphically displayed in Fig. 4. A t-test for dependent samples showed a significant difference in pre-service teachers’ judgments of students’ interest in solving the two types of problems [t(162) = 14.33, p < 0.01]. Cohen’s d = 1.12 indicated a large effect. As hypothesized, this means that pre-service teachers believed that solving problems with a connection to reality triggered more interest in students than solving problems without a connection to reality. | AD15: 7(373) | AE15: 163 | AF15: 1.12 | AG15: d | AI15: < 0.01 | AJ15: l (<) | AK15: NA (not reported) | AN15: 80 | AR15: p < 0.01 | AS15: l (<) | AT15: NA (not reported) | AW15: 2 - close | AY15: LR
A16: validated - discarded | B16: double | C16: Sarah | E16: additional_studies1_1 | F16: additional_studies1_c | G16: SAJ | H16: 45427 | I16: 45624 | J16: this effect was not explored in the original paper | K16: discarded because this is an extension that cannot be paired up with an original finding | L16: Rellensmann, J., & Schukajlow, S. (2017). Does students’ interest in a mathematical problem depend on the problem’s connection to reality? An analysis of students’ interest and pre-service teachers’ judgments of students’ interest in problems with and without a connection to reality. ZDM, 49, 367-378. https://doi.org/10.1007/s11858-016-0819-3 | M16: 10.1007/s11858-016-0819-3 | N16: 1 | O16: =hyperlink(vlookup(lower(M16),'File Links'!A:B, 2, FALSE), SUBSTITUTE(lower(M16), "/", "--") & ".pdf") -> 10.1007--s11858-016-0819-3.pdf | P16: {=HYPERLINK(INDEX('File Links'!B:B, MATCH(O16, 'File Links'!C:C, 0)))} -> https://drive.google.com/file/d/1A3A0XWewbvFp536VbiCjIAYxdIJwVP-9/view?usp=drivesdk | Q16: García-Cerdá, C., Segura, C., & Ferrando, I. (2024). Influence of the Type of Mathematical Problems on Students’ and Pre-service Teachers’ Interest and Performance. A Replication and Elaboration Study. Implementation and Replication Studies in Mathematics Education, 1(aop), 1-35. https://doi.org/10.1163/26670127-bja10017 | R16: 10.1163/26670127-bja10017 | T16: 1 | U16: =hyperlink(vlookup(lower(R16),'File Links'!E:F, 2, FALSE), SUBSTITUTE(lower(R16), "/", "--") & ".pdf") -> 10.1163--26670127-bja10017.pdf | V16: Title - "A replication and elaboration study" Abstract - "... the process of conceptual replication of Rellensmann and Schukajlow’s (2017) research..." | W16: {=HYPERLINK(INDEX('File Links'!B:B, MATCH(U16, 'File Links'!C:C, 0)))} -> #N/A | Y16: Education | Z16: interest in mathematics | AA16: mathematics, interest, students, pre-service teachers, diagnostic competence, real-world problems, performance, problem-solving | AB16: Influence of the Type of Mathematical Problems on Student Performance | AN16: 80 | AO16: 0.27 | AP16: W | AQ16: Kendells W = X2/N(K-1), X2 = 43.61, N = 80, K = 3 W = 43.61/ (80*(3-1)), W = 43.61/ (160), W ~ 0.27 | AR16: p < 0.01 | AS16: l (<) | AT16: NA (not reported) | AW16: extension | AY16: LR
A17: validated - discarded | B17: double | C17: Sarah | E17: additional_studies1_1 | F17: additional_studies1_d | G17: SAJ | H17: 45427 | I17: 45624 | J17: this effect was not explored in the original paper | K17: discarded because this is an extension that cannot be paired up with an original finding | L17: Rellensmann, J., & Schukajlow, S. (2017). Does students’ interest in a mathematical problem depend on the problem’s connection to reality? An analysis of students’ interest and pre-service teachers’ judgments of students’ interest in problems with and without a connection to reality. ZDM, 49, 367-378. https://doi.org/10.1007/s11858-016-0819-3 | M17: 10.1007/s11858-016-0819-3 | N17: 1 | O17: =hyperlink(vlookup(lower(M17),'File Links'!A:B, 2, FALSE), SUBSTITUTE(lower(M17), "/", "--") & ".pdf") -> 10.1007--s11858-016-0819-3.pdf | P17: {=HYPERLINK(INDEX('File Links'!B:B, MATCH(O17, 'File Links'!C:C, 0)))} -> https://drive.google.com/file/d/1A3A0XWewbvFp536VbiCjIAYxdIJwVP-9/view?usp=drivesdk | Q17: García-Cerdá, C., Segura, C., & Ferrando, I. (2024). Influence of the Type of Mathematical Problems on Students’ and Pre-service Teachers’ Interest and Performance. A Replication and Elaboration Study. Implementation and Replication Studies in Mathematics Education, 1(aop), 1-35. https://doi.org/10.1163/26670127-bja10017 | R17: 10.1163/26670127-bja10017 | T17: 1 | U17: =hyperlink(vlookup(lower(R17),'File Links'!E:F, 2, FALSE), SUBSTITUTE(lower(R17), "/", "--") & ".pdf") -> 10.1163--26670127-bja10017.pdf | V17: Title - "A replication and elaboration study" Abstract - "... the process of conceptual replication of Rellensmann and Schukajlow’s (2017) research..." | W17: {=HYPERLINK(INDEX('File Links'!B:B, MATCH(U17, 'File Links'!C:C, 0)))} -> #N/A | Y17: Education | Z17: interest in mathematics | AA17: mathematics, interest, students, pre-service teachers, diagnostic competence, real-world problems, performance, problem-solving | AB17: Influence of the Type of Mathematical Problems on Pre-service Teacher Performance | AN17: 80 | AO17: 0.68 | AP17: W | AQ17: Kendells W = X2/N(K-1), X2 = 108.75, N = 80, K = 3 W = 108.75/ (80*(3-1)), W = 108.75/ (160), W ~ 0.68 | AR17: p < 0.01 | AS17: l (<) | AT17: NA (not reported) | AW17: extension | AY17: LR
A18: validated - discarded | B18: double | C18: Sarah | E18: additional_studies1_1 | F18: additional_studies1_e | G18: SAJ | H18: 45427 | I18: 45624 | J18: this effect was not explored in the original paper | K18: discarded because this is an extension that cannot be paired up with an original finding | L18: Rellensmann, J., & Schukajlow, S. (2017). Does students’ interest in a mathematical problem depend on the problem’s connection to reality? An analysis of students’ interest and pre-service teachers’ judgments of students’ interest in problems with and without a connection to reality. ZDM, 49, 367-378. https://doi.org/10.1007/s11858-016-0819-3 | M18: 10.1007/s11858-016-0819-3 | N18: 1 | O18: =hyperlink(vlookup(lower(M18),'File Links'!A:B, 2, FALSE), SUBSTITUTE(lower(M18), "/", "--") & ".pdf") -> 10.1007--s11858-016-0819-3.pdf | P18: {=HYPERLINK(INDEX('File Links'!B:B, MATCH(O18, 'File Links'!C:C, 0)))} -> https://drive.google.com/file/d/1A3A0XWewbvFp536VbiCjIAYxdIJwVP-9/view?usp=drivesdk | Q18: García-Cerdá, C., Segura, C., & Ferrando, I. (2024). Influence of the Type of Mathematical Problems on Students’ and Pre-service Teachers’ Interest and Performance. A Replication and Elaboration Study. Implementation and Replication Studies in Mathematics Education, 1(aop), 1-35. https://doi.org/10.1163/26670127-bja10017 | R18: 10.1163/26670127-bja10017 | T18: 1 | U18: =hyperlink(vlookup(lower(R18),'File Links'!E:F, 2, FALSE), SUBSTITUTE(lower(R18), "/", "--") & ".pdf") -> 10.1163--26670127-bja10017.pdf | V18: Title - "A replication and elaboration study" Abstract - "... the process of conceptual replication of Rellensmann and Schukajlow’s (2017) research..." | W18: {=HYPERLINK(INDEX('File Links'!B:B, MATCH(U18, 'File Links'!C:C, 0)))} -> #N/A | Y18: Education | Z18: interest in mathematics | AA18: mathematics, interest, students, pre-service teachers, diagnostic competence, real-world problems, performance, problem-solving | AB18: Influence of the Type of Mathematical Problems on Student Interest*Performance relationship | AN18: 80 | AO18: intramathematical problem r = 0.25, word problem r = 0.29, modelling problem r = 0.31 | AP18: r | AR18: intramathematical problem p < 0.05, word problem p < 0.01, modelling problem p < 0.01 | AS18: l (<) | AT18: NA (not reported) | AW18: extension | AY18: LR
A19: validated - discarded | B19: double | C19: Sarah | E19: additional_studies1_1 | F19: additional_studies1_f | G19: SAJ | H19: 45427 | I19: 45624 | J19: this effect was not explored in the original paper | K19: discarded because this is an extension that cannot be paired up with an original finding | L19: Rellensmann, J., & Schukajlow, S. (2017). Does students’ interest in a mathematical problem depend on the problem’s connection to reality? An analysis of students’ interest and pre-service teachers’ judgments of students’ interest in problems with and without a connection to reality. ZDM, 49, 367-378. https://doi.org/10.1007/s11858-016-0819-3 | M19: 10.1007/s11858-016-0819-3 | N19: 1 | O19: =hyperlink(vlookup(lower(M19),'File Links'!A:B, 2, FALSE), SUBSTITUTE(lower(M19), "/", "--") & ".pdf") -> 10.1007--s11858-016-0819-3.pdf | P19: {=HYPERLINK(INDEX('File Links'!B:B, MATCH(O19, 'File Links'!C:C, 0)))} -> https://drive.google.com/file/d/1A3A0XWewbvFp536VbiCjIAYxdIJwVP-9/view?usp=drivesdk | Q19: García-Cerdá, C., Segura, C., & Ferrando, I. (2024). Influence of the Type of Mathematical Problems on Students’ and Pre-service Teachers’ Interest and Performance. A Replication and Elaboration Study. Implementation and Replication Studies in Mathematics Education, 1(aop), 1-35. https://doi.org/10.1163/26670127-bja10017 | R19: 10.1163/26670127-bja10017 | T19: 1 | U19: =hyperlink(vlookup(lower(R19),'File Links'!E:F, 2, FALSE), SUBSTITUTE(lower(R19), "/", "--") & ".pdf") -> 10.1163--26670127-bja10017.pdf | V19: Title - "A replication and elaboration study" Abstract - "... the process of conceptual replication of Rellensmann and Schukajlow’s (2017) research..." | W19: {=HYPERLINK(INDEX('File Links'!B:B, MATCH(U19, 'File Links'!C:C, 0)))} -> #N/A | Y19: Education | Z19: interest in mathematics | AA19: mathematics, interest, students, pre-service teachers, diagnostic competence, real-world problems, performance, problem-solving | AB19: Influence of the Type of Mathematical Problems on Pre-service Teacher Interest*Performance relationship | AN19: 80 | AO19: intramathematical problem r = 0.48, word problem r = 0.28, modelling problem r = 0.35 | AP19: r | AR19: intramathematical problem p < 0.01, word problem p < 0.01, modelling problem p < 0.01 | AS19: l (<) | AT19: NA (not reported) | AW19: extension | AY19: LR
A20: assigned | B20: double | C20: Daniel | E20: additional_studies10 | F20: additional_studies10_d | G20: Daniel Manrique-Castano | I20: 45683 | J20: The coding of this study was extremely challenging for me and I could not complete it. I feel that the replication study is extremely unclear in describing what effects they are trying to replicate. Although the replication article provides the information for the original research article (DM&D column) in Tables 3 and 4 (p. 11), it is extremely difficult for me to track this information in the original research article. The replication does not specify which of the multiple comparisons they are referring to. In the lines I have filled in, I have been able to infer that the information refers only to the Spanish test. I spent several hours trying to decipher the information, but I am really frustrated because I would need much more time to read the article and the supplementary information to try to understand the issue. For this reason, I do not feel confident to complete the task. Sample size: The replication article reports a sample size of 19. This corresponds exclusively to the group of L2 Spanish speakers. However, my understanding is that the group of native Spanish speakers (n = 6) is also included in the comparisons. Again, it is extremely unclear which comparison the replication is trying to replicate. Therefore, I report 25 as the sample size in the lines I filled in. These entries, and the replication in general, need careful revision. | M20: 10.1111/lang.12161 | O20: =hyperlink(vlookup(lower(M20),'File Links'!A:B, 2, FALSE), SUBSTITUTE(lower(M20), "/", "--") & ".pdf") -> 10.1111--lang.12161.pdf | P20: {=HYPERLINK(INDEX('File Links'!B:B, MATCH(O20, 'File Links'!C:C, 0)))} -> https://drive.google.com/file/d/1W_KvsfbanYWBQG9nzoDuqDlzFW_jUYH2/view?usp=drivesdk | V20: A preregistered, close replication of Darcy et al. (2016) | W20: {=HYPERLINK(INDEX('File Links'!B:B, MATCH(U20, 'File Links'!C:C, 0)))} -> #N/A | Y20: Linguistics | Z20: Production accuracy - /e/ format | AA20: language processing, inhibitory control, second language, phonological processing | AB20: The study measured the production accuracy of /e/ format using a delayed sentence repetition task. | AN20: 58 | AO20: 3.31 | AP20: d | AQ20: 1.26 / 0.38 | AU20: yes | AV20: https://osf.io/w4gj2 | AW20: 2 - close
A21: assigned | B21: double | C21: Daniel | E21: additional_studies10 | F21: additional_studies10_e | G21: Daniel Manrique-Castano | I21: 45683 | J21: The coding of this study was extremely challenging for me and I could not complete it. I feel that the replication study is extremely unclear in describing what effects they are trying to replicate. Although the replication article provides the information for the original research article (DM&D column) in Tables 3 and 4 (p. 11), it is extremely difficult for me to track this information in the original research article. The replication does not specify which of the multiple comparisons they are referring to. In the lines I have filled in, I have been able to infer that the information refers only to the Spanish test. I spent several hours trying to decipher the information, but I am really frustrated because I would need much more time to read the article and the supplementary information to try to understand the issue. For this reason, I do not feel confident to complete the task. Sample size: The replication article reports a sample size of 19. This corresponds exclusively to the group of L2 Spanish speakers. However, my understanding is that the group of native Spanish speakers (n = 6) is also included in the comparisons. Again, it is extremely unclear which comparison the replication is trying to replicate. Therefore, I report 25 as the sample size in the lines I filled in. These entries, and the replication in general, need careful revision. | M21: 10.1111/lang.12161 | O21: =hyperlink(vlookup(lower(M21),'File Links'!A:B, 2, FALSE), SUBSTITUTE(lower(M21), "/", "--") & ".pdf") -> 10.1111--lang.12161.pdf | P21: {=HYPERLINK(INDEX('File Links'!B:B, MATCH(O21, 'File Links'!C:C, 0)))} -> https://drive.google.com/file/d/1W_KvsfbanYWBQG9nzoDuqDlzFW_jUYH2/view?usp=drivesdk | V21: A preregistered, close replication of Darcy et al. (2016) | W21: {=HYPERLINK(INDEX('File Links'!B:B, MATCH(U21, 'File Links'!C:C, 0)))} -> #N/A | Y21: Linguistics | Z21: Production accuracy - /ei̯/ ~ /e/ | AA21: language processing, inhibitory control, second language, phonological processing | AB21: The study measured the production accuracy of /ei/ ~ /e/ format using a delayed sentence repetition task. | AC21: Instead, they produced both vowels as a monophthongal /e/, with very little formant movement (1.18 for diphthongs vs. 0.92 for monophthongs, SD = 0.36), t(18) = 1.92, p = .071, r = .17, but distinguished them through duration. | AD21: p. 17 | AE21: 25 | AF21: 0.17 | AG21: r | AH21: t(18) = 1.92 | AI21: 0.71 | AJ21: e (=) | AK21: NA (not reported) | AL21: yes | AN21: 58 | AO21: 0.64 | AP21: d | AQ21: p. 11 | AR21: 0.001 | AS21: l (<) | AT21: NA (not reported) | AU21: yes | AV21: https://osf.io/w4gj2 | AW21: 2 - close
A22: assigned | B22: double | C22: Daniel | E22: additional_studies10 | F22: additional_studies10_f | G22: Daniel Manrique-Castano | I22: 45683 | J22: The coding of this study was extremely challenging for me and I could not complete it. I feel that the replication study is extremely unclear in describing what effects they are trying to replicate. Although the replication article provides the information for the original research article (DM&D column) in Tables 3 and 4 (p. 11), it is extremely difficult for me to track this information in the original research article. The replication does not specify which of the multiple comparisons they are referring to. In the lines I have filled in, I have been able to infer that the information refers only to the Spanish test. I spent several hours trying to decipher the information, but I am really frustrated because I would need much more time to read the article and the supplementary information to try to understand the issue. For this reason, I do not feel confident to complete the task. Sample size: The replication article reports a sample size of 19. This corresponds exclusively to the group of L2 Spanish speakers. However, my understanding is that the group of native Spanish speakers (n = 6) is also included in the comparisons. Again, it is extremely unclear which comparison the replication is trying to replicate. Therefore, I report 25 as the sample size in the lines I filled in. These entries, and the replication in general, need careful revision. | M22: 10.1111/lang.12161 | O22: =hyperlink(vlookup(lower(M22),'File Links'!A:B, 2, FALSE), SUBSTITUTE(lower(M22), "/", "--") & ".pdf") -> 10.1111--lang.12161.pdf | P22: {=HYPERLINK(INDEX('File Links'!B:B, MATCH(O22, 'File Links'!C:C, 0)))} -> https://drive.google.com/file/d/1W_KvsfbanYWBQG9nzoDuqDlzFW_jUYH2/view?usp=drivesdk | V22: A preregistered, close replication of Darcy et al. (2016) | W22: {=HYPERLINK(INDEX('File Links'!B:B, MATCH(U22, 'File Links'!C:C, 0)))} -> #N/A | Y22: Linguistics | Z22: Production accuracy - /ei̯/ z score | AA22: language processing, inhibitory control, second language, phonological processing | AB22: The study measured the production accuracy of /ei/ ~ z score format using a delayed sentence repetition task. | AN22: 58 | AO22: -2.67 | AP22: d | AQ22: 2.27 / 0.85 | AV22: https://osf.io/w4gj2 | AW22: 2 - close
A23: assigned | B23: double | C23: Daniel | E23: additional_studies10 | F23: additional_studies10_g | G23: Daniel Manrique-Castano | I23: 45683 | J23: The coding of this study was extremely challenging for me and I could not complete it. I feel that the replication study is extremely unclear in describing what effects they are trying to replicate. Although the replication article provides the information for the original research article (DM&D column) in Tables 3 and 4 (p. 11), it is extremely difficult for me to track this information in the original research article. The replication does not specify which of the multiple comparisons they are referring to. In the lines I have filled in, I have been able to infer that the information refers only to the Spanish test. I spent several hours trying to decipher the information, but I am really frustrated because I would need much more time to read the article and the supplementary information to try to understand the issue. For this reason, I do not feel confident to complete the task. Sample size: The replication article reports a sample size of 19. This corresponds exclusively to the group of L2 Spanish speakers. However, my understanding is that the group of native Spanish speakers (n = 6) is also included in the comparisons. Again, it is extremely unclear which comparison the replication is trying to replicate. Therefore, I report 25 as the sample size in the lines I filled in. These entries, and the replication in general, need careful revision. | M23: 10.1111/lang.12161 | O23: =hyperlink(vlookup(lower(M23),'File Links'!A:B, 2, FALSE), SUBSTITUTE(lower(M23), "/", "--") & ".pdf") -> 10.1111--lang.12161.pdf | P23: {=HYPERLINK(INDEX('File Links'!B:B, MATCH(O23, 'File Links'!C:C, 0)))} -> https://drive.google.com/file/d/1W_KvsfbanYWBQG9nzoDuqDlzFW_jUYH2/view?usp=drivesdk | V23: A preregistered, close replication of Darcy et al. (2016) | W23: {=HYPERLINK(INDEX('File Links'!B:B, MATCH(U23, 'File Links'!C:C, 0)))} -> #N/A | Y23: Linguistics | Z23: Production accuracy - Consonant accuracy | AA23: language processing, inhibitory control, second language, phonological processing | AB23: The study measured the production accuracy for consonants using a delayed sentence repetition task. | AN23: 58 | AO23: 1.94 | AP23: d | AQ23: 4.50 / 2.31 | AV23: https://osf.io/w4gj2 | AW23: 2 - close
A24: validated - discarded | B24: double | C24: Alexsandr | E24: additional_studies10_1 | F24: additional_studies10_a | G24: Aleksandr Pravednikov | H24: 45625 | I24: 45692 | J24: Claim text_r. Table 8, p. 14 Retrieval–induced inhibition: 1.02 (0.23), [...] Results of the current replication for the partial correlation analyses did not indicate statistically significant relationships, and effect sizes were small with 95% CIs crossing through zero. p. 16 | L24: Darcy, I., Mora, J. C., & Daidone, D. (2016). The role of inhibitory control in second language phonological processing. Language Learning, 66, 741–773. https://doi.org/10.1111/lang.12161 | M24: 10.1111/lang.12161 | N24: 1 | O24: =hyperlink(vlookup(lower(M24),'File Links'!A:B, 2, FALSE), SUBSTITUTE(lower(M24), "/", "--") & ".pdf") -> 10.1111--lang.12161.pdf | P24: {=HYPERLINK(INDEX('File Links'!B:B, MATCH(O24, 'File Links'!C:C, 0)))} -> https://drive.google.com/file/d/1W_KvsfbanYWBQG9nzoDuqDlzFW_jUYH2/view?usp=drivesdk | Q24: Huensch, A. (2024). Clarifying the role of inhibitory control in L2 phonological processing: A preregistered, close replication of Darcy et al.(2016). Studies in Second Language Acquisition, 1-21. https://doi.org/10.1017/S0272263124000238 | R24: 10.1017/S0272263124000238 | T24: 1 | U24: =hyperlink(vlookup(lower(R24),'File Links'!E:F, 2, FALSE), SUBSTITUTE(lower(R24), "/", "--") & ".pdf") -> 10.1017--s0272263124000238.pdf | V24: close replication | W24: {=HYPERLINK(INDEX('File Links'!B:B, MATCH(U24, 'File Links'!C:C, 0)))} -> #N/A | Y24: Linguistics | Z24: Second Language Phonological Processing | AA24: language processing, inhibitory control, second language, phonological processing | AB24: Role of inhibitory control in L2 phonological processing (Retrieval–induced inhibition) | AC24: Table 7 summarizes the results of correlation analyses between inhibition scores and the four phonological accuracy scores (controlling for proficiency). These correlations show that error rate and z scores in ABX perception were significantly negatively correlated with inhibition scores, which indicates that individuals with higher inhibition scores also obtained lower error rates and lower (more targetlike)zscores in vowel perception. | AD24: 21 | AE24: 18 | AJ24: l (<) | AK24: NA (not reported) | AN24: 58 | AT24: NA (not reported) | AW24: close | AY24: LR
A25: validated - chosen | B25: double | C25: Alexsandr | E25: additional_studies10_1 | F25: additional_studies10_b | G25: Aleksandr Pravednikov | H25: 45625 | I25: 45692 | J25: Claim text_r. Table 8, p. 14 ABX error (vowels) 19.2 (13.2) [...] Results of the current replication for the partial correlation analyses did not indicate statistically significant relationships, and effect sizes were small with 95% CIs crossing through zero. p. 16 | K25: coded as nested due to hierarchical regression; a fourth effect is reported for the replication but NA for the original study; p_val_tails_r coded as one because it says in the note "as reported in DM&D", where p-values are one-tailed. Note that in the table two-tailed CIs are reported | L25: Darcy, I., Mora, J. C., & Daidone, D. (2016). The role of inhibitory control in second language phonological processing. Language Learning, 66, 741–773. https://doi.org/10.1111/lang.12161 | M25: 10.1111/lang.12161 | N25: 1 | O25: =hyperlink(vlookup(lower(M25),'File Links'!A:B, 2, FALSE), SUBSTITUTE(lower(M25), "/", "--") & ".pdf") -> 10.1111--lang.12161.pdf | P25: {=HYPERLINK(INDEX('File Links'!B:B, MATCH(O25, 'File Links'!C:C, 0)))} -> https://drive.google.com/file/d/1W_KvsfbanYWBQG9nzoDuqDlzFW_jUYH2/view?usp=drivesdk | Q25: Huensch, A. (2024). Clarifying the role of inhibitory control in L2 phonological processing: A preregistered, close replication of Darcy et al.(2016). Studies in Second Language Acquisition, 1-21. https://doi.org/10.1017/S0272263124000238 | R25: 10.1017/S0272263124000238 | T25: 1 | U25: =hyperlink(vlookup(lower(R25),'File Links'!E:F, 2, FALSE), SUBSTITUTE(lower(R25), "/", "--") & ".pdf") -> 10.1017--s0272263124000238.pdf | V25: close replication | W25: {=HYPERLINK(INDEX('File Links'!B:B, MATCH(U25, 'File Links'!C:C, 0)))} -> #N/A | Y25: Linguistics | Z25: Second Language Phonological Processing | AA25: language processing, inhibitory control, second language, phonological processing | AB25: Role of inhibitory control in L2 phonological processing (ABX error (vowels)) | AC25: Table 7 summarizes the results of correlation analyses between inhibition scores and the four phonological accuracy scores (controlling for proficiency). These correlations show that error rate and z scores in ABX perception were significantly negatively correlated with inhibition scores, which indicates that individuals with higher inhibition scores also obtained lower error rates and lower (more targetlike)zscores in vowel perception. | AD25: 33 | AE25: 18 | AF25: -0.42 | AG25: partial r | AH25: p. 23 | AI25: 0.01 | AJ25: l (<) | AK25: 1 (one) | AL25: yes | AM25: NA | AN25: 58 | AO25: -0.13 | AP25: partial r | AQ25: p. 15, Table 10 | AR25: 0.379 | AS25: e (=) | AT25: 1 (one) | AU25: yes | AV25: https://osf.io/w4gj2 | AW25: close | AY25: LR
